Workbook

Sheet 使い方
B2: シェア率回収_ALL(各エリアのシェア率を月ごとに集めて、エリア別・販路別・店舗別のシェア率と、月次推移のグラフを出すブック)
B4: 【しくみ】各エリアのマスタ(シート「店舗別シェア率」のB6:U65)を、「各エリア_マスタURL貼付」の行ごとに「データ_全エリア」へ集める。そのとき、URL貼付シートの「月」を、データ_全エリアのB列に付ける。→「集計_エリア別」(C3)「集計_販路」(B3)「集計_販路エリア」(C3)「集計_各エリア店舗別シェア率」(B4)は、それぞれ()内のセルの「対象月」で選んだ月を集計する。→「集計_店舗別月次推移」は、エリアと店舗を選ぶと、月ごとのシェアの推移を表とグラフで表示する(店舗名を空欄にすると、選んだエリア(ALLなら全国)の合計になる)。
B5: 【触るのは「各エリア_マスタURL貼付」だけ】黄色のセルに、エリア・月(各月1日の日付)・ブックのURL・シート名を入れる。
B6: 【新しい月を追加する手順】①「各エリア_マスタURL貼付」の一番下に、8エリア分の行を足す(エリア名・月・URL・シート名)。②初回のみ、空きセルで =IMPORTRANGE("URL","シート名!B2")を入れて「アクセスを許可」を押す(エリアのブックごとに1回)。③各集計シートの「対象月」を、新しい月に切り替える。
B7: 【エリアごとのシェア率の出し方】店舗のシェア率の平均ではなく、分母(総販・新規/MNP)で重み付けして計算している。
B8: エリアのシェア率 = Σ(店舗のシェア率 × 店舗の分母) ÷ Σ(店舗の分母)。「データ_全エリア」のV〜AG列は、この「シェア率 × 分母」の補助列。
B9: 【取り込み元のルール】各エリアのマスタの「店舗別シェア率」で、B〜U列の並びを変えないこと(列の挿入・削除は禁止)。月はマスタには入れず、URL貼付シートで指定する。
B10: 【A列】どのシートも、A列は空欄にしてある(使わない)。
B11: 【数式が崩れたとき】「数式メモ」シートに、主要な数式を文字で控えてある。
B12: 【データの範囲】「データ_全エリア」は4〜6000行。月が増えて足りなくなったら、各集計シートの 6000 を広げる。
B13: 【シート一覧】使い方 / 各エリア_マスタURL貼付 / データ_全エリア / 集計_エリア別 / 集計_販路 / 集計_販路エリア / 集計_各エリア店舗別シェア率 / 集計_店舗別月次推移 / 数式メモ / TIR店舗一覧

Sheet 各エリア_マスタURL貼付
B1: 黄色のセルにURLを入れる | D1: 月は各月1日の日付で入れる。URLはその月のマスタのURL。行は下に足していく。
B2: エリア | C2: 月 | D2: ブックのURL | E2: シート名 | F2: 接続状況 | H2: 月一覧(自動・編集NG)
B3: 北海道 | C3: 46266 | E3: 店舗別シェア率 | F3: =IFERROR(__xludf.DUMMYFUNCTION("IF($D3="""",""未設定"",IF(ISERROR(IMPORTRANGE($D3,""'""&$E3&""'!B2"")),""未接続(アクセス許可が必要)"",""OK""))"),"未設定") -> 未設定 | H3: =IFERROR(__xludf.DUMMYFUNCTION("IFERROR(SORT(UNIQUE(FILTER(C3:C1024,C3:C1024<>"""")),1,FALSE),"""")"),46357.0) -> 46357
B4: 東北 | C4: 46266 | E4: 店舗別シェア率 | F4: =IFERROR(__xludf.DUMMYFUNCTION("IF($D4="""",""未設定"",IF(ISERROR(IMPORTRANGE($D4,""'""&$E4&""'!B2"")),""未接続(アクセス許可が必要)"",""OK""))"),"未設定") -> 未設定 | H4: =IFERROR(__xludf.DUMMYFUNCTION("""COMPUTED_VALUE"""),46327.0) -> 46327
B5: 関東 | C5: 46266 | E5: CESシェア率回収 | F5: =IFERROR(__xludf.DUMMYFUNCTION("IF($D5="""",""未設定"",IF(ISERROR(IMPORTRANGE($D5,""'""&$E5&""'!B2"")),""未接続(アクセス許可が必要)"",""OK""))"),"未設定") -> 未設定 | H5: =IFERROR(__xludf.DUMMYFUNCTION("""COMPUTED_VALUE"""),46296.0) -> 46296
B6: 信越 | C6: 46266 | E6: 店舗別シェア率 | F6: =IFERROR(__xludf.DUMMYFUNCTION("IF($D6="""",""未設定"",IF(ISERROR(IMPORTRANGE($D6,""'""&$E6&""'!B2"")),""未接続(アクセス許可が必要)"",""OK""))"),"未設定") -> 未設定 | H6: =IFERROR(__xludf.DUMMYFUNCTION("""COMPUTED_VALUE"""),46266.0) -> 46266
B7: 中部 | C7: 46266 | E7: 店舗別シェア率 | F7: =IFERROR(__xludf.DUMMYFUNCTION("IF($D7="""",""未設定"",IF(ISERROR(IMPORTRANGE($D7,""'""&$E7&""'!B2"")),""未接続(アクセス許可が必要)"",""OK""))"),"未設定") -> 未設定
B8: 関西 | C8: 46266 | E8: 店舗別シェア率 | F8: =IFERROR(__xludf.DUMMYFUNCTION("IF($D8="""",""未設定"",IF(ISERROR(IMPORTRANGE($D8,""'""&$E8&""'!B2"")),""未接続(アクセス許可が必要)"",""OK""))"),"未設定") -> 未設定
B9: 中四国 | C9: 46266 | E9: 店舗別シェア率 | F9: =IFERROR(__xludf.DUMMYFUNCTION("IF($D9="""",""未設定"",IF(ISERROR(IMPORTRANGE($D9,""'""&$E9&""'!B2"")),""未接続(アクセス許可が必要)"",""OK""))"),"未設定") -> 未設定
B10: 九州・沖縄 | C10: 46266 | E10: 店舗別シェア率 | F10: =IFERROR(__xludf.DUMMYFUNCTION("IF($D10="""",""未設定"",IF(ISERROR(IMPORTRANGE($D10,""'""&$E10&""'!B2"")),""未接続(アクセス許可が必要)"",""OK""))"),"未設定") -> 未設定
B11: 北海道 | C11: 46296 | D11: https://docs.google.com/spreadsheets/d/1HQmMw_eziFnqzbZBgjBJBxCgKpzZ3nBOXESYZ8n0RFA/edit?gid=1169211779#gid=1169211779 | E11: 店舗別シェア率 | F11: =IFERROR(__xludf.DUMMYFUNCTION("IF($D11="""",""未設定"",IF(ISERROR(IMPORTRANGE($D11,""'""&$E11&""'!B2"")),""未接続(アクセス許可が必要)"",""OK""))"),"OK") -> OK
B12: 東北 | C12: 46296 | E12: 店舗別シェア率 | F12: =IFERROR(__xludf.DUMMYFUNCTION("IF($D12="""",""未設定"",IF(ISERROR(IMPORTRANGE($D12,""'""&$E12&""'!B2"")),""未接続(アクセス許可が必要)"",""OK""))"),"未設定") -> 未設定
B13: 関東 | C13: 46296 | D13: https://docs.google.com/spreadsheets/d/1FC01E-bDaShIRILMefsepFfA8yNt8BDjGhHZDlqZ0gQ/edit?gid=173124311#gid=173124311 | E13: CESシェア率回収 | F13: =IFERROR(__xludf.DUMMYFUNCTION("IF($D13="""",""未設定"",IF(ISERROR(IMPORTRANGE($D13,""'""&$E13&""'!B2"")),""未接続(アクセス許可が必要)"",""OK""))"),"OK") -> OK
B14: 信越 | C14: 46296 | D14: https://docs.google.com/spreadsheets/d/1CysG2mPIAHK5LHa7IAxotVT4BXZeF_ffoPWhat6Buvs/edit?pli=1&gid=1208661004#gid=1208661004 | E14: 店舗別シェア率 | F14: =IFERROR(__xludf.DUMMYFUNCTION("IF($D14="""",""未設定"",IF(ISERROR(IMPORTRANGE($D14,""'""&$E14&""'!B2"")),""未接続(アクセス許可が必要)"",""OK""))"),"OK") -> OK
B15: 中部 | C15: 46296 | E15: 店舗別シェア率 | F15: =IFERROR(__xludf.DUMMYFUNCTION("IF($D15="""",""未設定"",IF(ISERROR(IMPORTRANGE($D15,""'""&$E15&""'!B2"")),""未接続(アクセス許可が必要)"",""OK""))"),"未設定") -> 未設定
B16: 関西 | C16: 46296 | E16: 店舗別シェア率 | F16: =IFERROR(__xludf.DUMMYFUNCTION("IF($D16="""",""未設定"",IF(ISERROR(IMPORTRANGE($D16,""'""&$E16&""'!B2"")),""未接続(アクセス許可が必要)"",""OK""))"),"未設定") -> 未設定
B17: 中四国 | C17: 46296 | E17: 店舗別シェア率 | F17: =IFERROR(__xludf.DUMMYFUNCTION("IF($D17="""",""未設定"",IF(ISERROR(IMPORTRANGE($D17,""'""&$E17&""'!B2"")),""未接続(アクセス許可が必要)"",""OK""))"),"未設定") -> 未設定
B18: 九州・沖縄 | C18: 46296 | E18: 店舗別シェア率 | F18: =IFERROR(__xludf.DUMMYFUNCTION("IF($D18="""",""未設定"",IF(ISERROR(IMPORTRANGE($D18,""'""&$E18&""'!B2"")),""未接続(アクセス許可が必要)"",""OK""))"),"未設定") -> 未設定
B19: 北海道 | C19: 46327 | D19: https://docs.google.com/spreadsheets/d/1WKwLcLgVV_7EA1xhpH5oDhrJznfU2GoPsvu6i_-nhEQ/edit?gid=1169211779#gid=1169211779 | E19: 店舗別シェア率 | F19: =IFERROR(__xludf.DUMMYFUNCTION("IF($D19="""",""未設定"",IF(ISERROR(IMPORTRANGE($D19,""'""&$E19&""'!B2"")),""未接続(アクセス許可が必要)"",""OK""))"),"OK") -> OK
B20: 東北 | C20: 46327 | D20: https://docs.google.com/spreadsheets/d/1LFC3bOKOjnaFY8UQ8VRQi9q1gvSGE7PvaYTDNQj8RP8/edit?gid=1169211779#gid=1169211779 | E20: 店舗別シェア率 | F20: =IFERROR(__xludf.DUMMYFUNCTION("IF($D20="""",""未設定"",IF(ISERROR(IMPORTRANGE($D20,""'""&$E20&""'!B2"")),""未接続(アクセス許可が必要)"",""OK""))"),"OK") -> OK
B21: 関東 | C21: 46327 | D21: https://docs.google.com/spreadsheets/d/1LI9_bnOc87G-uwrO4xOBg7C8ugZ9QIk9eosfRSqvXmw/edit?gid=1991733541#gid=1991733541 | E21: CESシェア率回収 | F21: =IFERROR(__xludf.DUMMYFUNCTION("IF($D21="""",""未設定"",IF(ISERROR(IMPORTRANGE($D21,""'""&$E21&""'!B2"")),""未接続(アクセス許可が必要)"",""OK""))"),"OK") -> OK
B22: 信越 | C22: 46327 | E22: 店舗別シェア率 | F22: =IFERROR(__xludf.DUMMYFUNCTION("IF($D22="""",""未設定"",IF(ISERROR(IMPORTRANGE($D22,""'""&$E22&""'!B2"")),""未接続(アクセス許可が必要)"",""OK""))"),"未設定") -> 未設定
B23: 中部 | C23: 46327 | D23: https://docs.google.com/spreadsheets/d/1xkO-x3oKEjKEh9o1tBgF70i-f_SH5vk3NzoPDShDunU/edit?gid=1169211779#gid=1169211779 | E23: 店舗別シェア率 | F23: =IFERROR(__xludf.DUMMYFUNCTION("IF($D23="""",""未設定"",IF(ISERROR(IMPORTRANGE($D23,""'""&$E23&""'!B2"")),""未接続(アクセス許可が必要)"",""OK""))"),"OK") -> OK
B24: 関西 | C24: 46327 | D24: https://docs.google.com/spreadsheets/d/1qiFm_6D1uHvvLy0aBYEzfqL0LPKxjbBCKA9FknlHvvU/edit?gid=1169211779#gid=1169211779 | E24: 店舗別シェア率 | F24: =IFERROR(__xludf.DUMMYFUNCTION("IF($D24="""",""未設定"",IF(ISERROR(IMPORTRANGE($D24,""'""&$E24&""'!B2"")),""未接続(アクセス許可が必要)"",""OK""))"),"OK") -> OK
B25: 中四国 | C25: 46327 | D25: https://docs.google.com/spreadsheets/d/11mCKxxNiQxn8hboizpmYKdY7cG4sG6tgO17FgdlN5EA/edit?gid=1169211779#gid=1169211779 | E25: 店舗別シェア率 | F25: =IFERROR(__xludf.DUMMYFUNCTION("IF($D25="""",""未設定"",IF(ISERROR(IMPORTRANGE($D25,""'""&$E25&""'!B2"")),""未接続(アクセス許可が必要)"",""OK""))"),"OK") -> OK
B26: 九州・沖縄 | C26: 46327 | D26: https://docs.google.com/spreadsheets/d/1XfSk3wS9zWKljCqL9ar8d6wt6FBhVHm-aWZ2NDYT0hI/edit?gid=1169211779#gid=1169211779 | E26: 店舗別シェア率 | F26: =IFERROR(__xludf.DUMMYFUNCTION("IF($D26="""",""未設定"",IF(ISERROR(IMPORTRANGE($D26,""'""&$E26&""'!B2"")),""未接続(アクセス許可が必要)"",""OK""))"),"OK") -> OK
B27: 北海道 | C27: 46357 | E27: 店舗別シェア率 | F27: =IFERROR(__xludf.DUMMYFUNCTION("IF($D27="""",""未設定"",IF(ISERROR(IMPORTRANGE($D27,""'""&$E27&""'!B2"")),""未接続(アクセス許可が必要)"",""OK""))"),"未設定") -> 未設定
B28: 東北 | C28: 46357 | E28: 店舗別シェア率 | F28: =IFERROR(__xludf.DUMMYFUNCTION("IF($D28="""",""未設定"",IF(ISERROR(IMPORTRANGE($D28,""'""&$E28&""'!B2"")),""未接続(アクセス許可が必要)"",""OK""))"),"未設定") -> 未設定
B29: 関東 | C29: 46357 | E29: CESシェア率回収 | F29: =IFERROR(__xludf.DUMMYFUNCTION("IF($D29="""",""未設定"",IF(ISERROR(IMPORTRANGE($D29,""'""&$E29&""'!B2"")),""未接続(アクセス許可が必要)"",""OK""))"),"未設定") -> 未設定
B30: 信越 | C30: 46357 | E30: 店舗別シェア率 | F30: =IFERROR(__xludf.DUMMYFUNCTION("IF($D30="""",""未設定"",IF(ISERROR(IMPORTRANGE($D30,""'""&$E30&""'!B2"")),""未接続(アクセス許可が必要)"",""OK""))"),"未設定") -> 未設定
B31: 中部 | C31: 46357 | E31: 店舗別シェア率 | F31: =IFERROR(__xludf.DUMMYFUNCTION("IF($D31="""",""未設定"",IF(ISERROR(IMPORTRANGE($D31,""'""&$E31&""'!B2"")),""未接続(アクセス許可が必要)"",""OK""))"),"未設定") -> 未設定
B32: 関西 | C32: 46357 | E32: 店舗別シェア率 | F32: =IFERROR(__xludf.DUMMYFUNCTION("IF($D32="""",""未設定"",IF(ISERROR(IMPORTRANGE($D32,""'""&$E32&""'!B2"")),""未接続(アクセス許可が必要)"",""OK""))"),"未設定") -> 未設定
B33: 中四国 | C33: 46357 | E33: 店舗別シェア率 | F33: =IFERROR(__xludf.DUMMYFUNCTION("IF($D33="""",""未設定"",IF(ISERROR(IMPORTRANGE($D33,""'""&$E33&""'!B2"")),""未接続(アクセス許可が必要)"",""OK""))"),"未設定") -> 未設定
B34: 九州・沖縄 | C34: 46357 | E34: 店舗別シェア率 | F34: =IFERROR(__xludf.DUMMYFUNCTION("IF($D34="""",""未設定"",IF(ISERROR(IMPORTRANGE($D34,""'""&$E34&""'!B2"")),""未接続(アクセス許可が必要)"",""OK""))"),"未設定") -> 未設定
B36: 入力例(参考。D列には、実際のURLを入れる):https://docs.google.com/spreadsheets/d/XXXXXXXXXXXXXXXX/edit
B37: ※エリア名は「TIR店舗一覧」のB列と同じ表記にする。E列は、各エリアのブックの取り込み元シート名(通常は変更しない)。

Sheet データ_全エリア
C1: 取り込みデータ(自動表示のため編集NG)
G2: 総販ベース | M2: 新規/MNPベース | V2: 補助列(自動表示・編集NG)
B3: 月 | C3: エリア | D3: 店舗コード | E3: 店舗名 | F3: 楽天総販 | G3: ドコモ | H3: au | I3: SB | J3: UQ | K3: Yモバ | L3: 楽天 | M3: ドコモ | N3: au | O3: SB | P3: UQ | Q3: Yモバ | R3: 楽天 | S3: 総販 | T3: 新規/MNP | U3: 販路 | V3: ドコモのシェア率 × 総販 | W3: auのシェア率 × 総販 | X3: SBのシェア率 × 総販 | Y3: UQのシェア率 × 総販 | Z3: Yモバのシェア率 × 総販 | AA3: 楽天のシェア率 × 総販 | AB3: ドコモのシェア率 × 新規/MNP | AC3: auのシェア率 × 新規/MNP | AD3: SBのシェア率 × 新規/MNP | AE3: UQのシェア率 × 新規/MNP | AF3: Yモバのシェア率 × 新規/MNP | AG3: 楽天のシェア率 × 新規/MNP
B4: =IFERROR(__xludf.DUMMYFUNCTION("IFERROR(LET(u,FILTER('各エリア_マスタURL貼付'!C3:E1024,'各エリア_マスタURL貼付'!D3:D1024<>""""), d,REDUCE(MAKEARRAY(1,21,LAMBDA(r,c,"""")),SEQUENCE(ROWS(u)),LAMBDA(a,i,VSTACK(a,LET( b,IFERROR(IMPORTRANGE(INDEX(u,i,2),""'""&INDEX(u,i,3)&""'!B6:U65""),MAKEARRAY(1,20,LAMBDA(r"&",c,""""))), HSTACK(MAKEARRAY(ROWS(b),1,LAMBDA(r,c,INDEX(u,i,1))),b))))), CHOOSECOLS(FILTER(d,INDEX(d,0,3)<>""""),1,2,3,4,5,6,7,8,9,10,11,12,13,14,15,16,17,20,21)),"""")"),46296.0) -> 46296 | C4: =IFERROR(__xludf.DUMMYFUNCTION("""COMPUTED_VALUE"""),"北海道") -> 北海道 | D4: =IFERROR(__xludf.DUMMYFUNCTION("""COMPUTED_VALUE"""),8327.0) -> 8327 | E4: =IFERROR(__xludf.DUMMYFUNCTION("""COMPUTED_VALUE"""),"ケーズデンキ 北見店") -> ケーズデンキ 北見店 | F4: =IFERROR(__xludf.DUMMYFUNCTION("""COMPUTED_VALUE"""),37.0) -> 37 | G4: =IFERROR(__xludf.DUMMYFUNCTION("""COMPUTED_VALUE"""),0.0) -> 0 | H4: =IFERROR(__xludf.DUMMYFUNCTION("""COMPUTED_VALUE"""),0.0) -> 0 | I4: =IFERROR(__xludf.DUMMYFUNCTION("""COMPUTED_VALUE"""),0.0) -> 0 | J4: =IFERROR(__xludf.DUMMYFUNCTION("""COMPUTED_VALUE"""),0.0) -> 0 | K4: =IFERROR(__xludf.DUMMYFUNCTION("""COMPUTED_VALUE"""),0.0) -> 0 | L4: =IFERROR(__xludf.DUMMYFUNCTION("""COMPUTED_VALUE"""),1.0) -> 1 | M4: =IFERROR(__xludf.DUMMYFUNCTION("""COMPUTED_VALUE"""),0.0) -> 0 | N4: =IFERROR(__xludf.DUMMYFUNCTION("""COMPUTED_VALUE"""),0.0) -> 0 | O4: =IFERROR(__xludf.DUMMYFUNCTION("""COMPUTED_VALUE"""),0.0) -> 0 | P4: =IFERROR(__xludf.DUMMYFUNCTION("""COMPUTED_VALUE"""),0.0) -> 0 | Q4: =IFERROR(__xludf.DUMMYFUNCTION("""COMPUTED_VALUE"""),0.0) -> 0 | R4: =IFERROR(__xludf.DUMMYFUNCTION("""COMPUTED_VALUE"""),1.0) -> 1 | S4: =IFERROR(__xludf.DUMMYFUNCTION("""COMPUTED_VALUE"""),37.0) -> 37 | T4: =IFERROR(__xludf.DUMMYFUNCTION("""COMPUTED_VALUE"""),37.0) -> 37 | U4: {=IF($D4="","",IFERROR(_xlfn.XLOOKUP($D4,'TIR店舗一覧'!$D:$D,'TIR店舗一覧'!$E:$E,""),""))} -> KS | V4: {=IF($D$4:$D$6000="","",IFERROR(G$4:L$6000*$S$4:$S$6000,0))} -> 0 | W4: 0 | X4: 0 | Y4: 0 | Z4: 0 | AA4: 37 | AB4: {=IF($D$4:$D$6000="","",IFERROR(M$4:R$6000*$T$4:$T$6000,0))} -> 0 | AC4: 0 | AD4: 0 | AE4: 0 | AF4: 0 | AG4: 37
B5: =IFERROR(__xludf.DUMMYFUNCTION("""COMPUTED_VALUE"""),46296.0) -> 46296 | C5: =IFERROR(__xludf.DUMMYFUNCTION("""COMPUTED_VALUE"""),"北海道") -> 北海道 | D5: =IFERROR(__xludf.DUMMYFUNCTION("""COMPUTED_VALUE"""),8359.0) -> 8359 | E5: =IFERROR(__xludf.DUMMYFUNCTION("""COMPUTED_VALUE"""),"ケーズデンキ 平岸店") -> ケーズデンキ 平岸店 | F5: =IFERROR(__xludf.DUMMYFUNCTION("""COMPUTED_VALUE"""),41.0) -> 41 | G5: =IFERROR(__xludf.DUMMYFUNCTION("""COMPUTED_VALUE"""),0.0) -> 0 | H5: =IFERROR(__xludf.DUMMYFUNCTION("""COMPUTED_VALUE"""),0.0) -> 0 | I5: =IFERROR(__xludf.DUMMYFUNCTION("""COMPUTED_VALUE"""),0.0) -> 0 | J5: =IFERROR(__xludf.DUMMYFUNCTION("""COMPUTED_VALUE"""),0.0) -> 0 | K5: =IFERROR(__xludf.DUMMYFUNCTION("""COMPUTED_VALUE"""),0.0) -> 0 | L5: =IFERROR(__xludf.DUMMYFUNCTION("""COMPUTED_VALUE"""),1.0) -> 1 | M5: =IFERROR(__xludf.DUMMYFUNCTION("""COMPUTED_VALUE"""),0.0) -> 0 | N5: =IFERROR(__xludf.DUMMYFUNCTION("""COMPUTED_VALUE"""),0.0) -> 0 | O5: =IFERROR(__xludf.DUMMYFUNCTION("""COMPUTED_VALUE"""),0.0) -> 0 | P5: =IFERROR(__xludf.DUMMYFUNCTION("""COMPUTED_VALUE"""),0.0) -> 0 | Q5: =IFERROR(__xludf.DUMMYFUNCTION("""COMPUTED_VALUE"""),0.0) -> 0 | R5: =IFERROR(__xludf.DUMMYFUNCTION("""COMPUTED_VALUE"""),1.0) -> 1 | S5: =IFERROR(__xludf.DUMMYFUNCTION("""COMPUTED_VALUE"""),41.0) -> 41 | T5: =IFERROR(__xludf.DUMMYFUNCTION("""COMPUTED_VALUE"""),41.0) -> 41 | U5: {=IF($D5="","",IFERROR(_xlfn.XLOOKUP($D5,'TIR店舗一覧'!$D:$D,'TIR店舗一覧'!$E:$E,""),""))} -> KS | V5: 0 | W5: 0 | X5: 0 | Y5: 0 | Z5: 0 | AA5: 41 | AB5: 0 | AC5: 0 | AD5: 0 | AE5: 0 | AF5: 0 | AG5: 41
B6: =IFERROR(__xludf.DUMMYFUNCTION("""COMPUTED_VALUE"""),46296.0) -> 46296 | C6: =IFERROR(__xludf.DUMMYFUNCTION("""COMPUTED_VALUE"""),"北海道") -> 北海道 | D6: =IFERROR(__xludf.DUMMYFUNCTION("""COMPUTED_VALUE"""),8358.0) -> 8358 | E6: =IFERROR(__xludf.DUMMYFUNCTION("""COMPUTED_VALUE"""),"ケーズデンキ 発寒店") -> ケーズデンキ 発寒店 | F6: =IFERROR(__xludf.DUMMYFUNCTION("""COMPUTED_VALUE"""),53.0) -> 53 | G6: =IFERROR(__xludf.DUMMYFUNCTION("""COMPUTED_VALUE"""),0.0) -> 0 | H6: =IFERROR(__xludf.DUMMYFUNCTION("""COMPUTED_VALUE"""),0.0) -> 0 | I6: =IFERROR(__xludf.DUMMYFUNCTION("""COMPUTED_VALUE"""),0.0) -> 0 | J6: =IFERROR(__xludf.DUMMYFUNCTION("""COMPUTED_VALUE"""),0.0) -> 0 | K6: =IFERROR(__xludf.DUMMYFUNCTION("""COMPUTED_VALUE"""),0.0) -> 0 | L6: =IFERROR(__xludf.DUMMYFUNCTION("""COMPUTED_VALUE"""),1.0) -> 1 | M6: =IFERROR(__xludf.DUMMYFUNCTION("""COMPUTED_VALUE"""),0.0) -> 0 | N6: =IFERROR(__xludf.DUMMYFUNCTION("""COMPUTED_VALUE"""),0.0) -> 0 | O6: =IFERROR(__xludf.DUMMYFUNCTION("""COMPUTED_VALUE"""),0.0) -> 0 | P6: =IFERROR(__xludf.DUMMYFUNCTION("""COMPUTED_VALUE"""),0.0) -> 0 | Q6: =IFERROR(__xludf.DUMMYFUNCTION("""COMPUTED_VALUE"""),0.0) -> 0 | R6: =IFERROR(__xludf.DUMMYFUNCTION("""COMPUTED_VALUE"""),1.0) -> 1 | S6: =IFERROR(__xludf.DUMMYFUNCTION("""COMPUTED_VALUE"""),53.0) -> 53 | T6: =IFERROR(__xludf.DUMMYFUNCTION("""COMPUTED_VALUE"""),53.0) -> 53 | U6: {=IF($D6="","",IFERROR(_xlfn.XLOOKUP($D6,'TIR店舗一覧'!$D:$D,'TIR店舗一覧'!$E:$E,""),""))} -> KS | V6: 0 | W6: 0 | X6: 0 | Y6: 0 | Z6: 0 | AA6: 53 | AB6: 0 | AC6: 0 | AD6: 0 | AE6: 0 | AF6: 0 | AG6: 53
B7: =IFERROR(__xludf.DUMMYFUNCTION("""COMPUTED_VALUE"""),46296.0) -> 46296 | C7: =IFERROR(__xludf.DUMMYFUNCTION("""COMPUTED_VALUE"""),"北海道") -> 北海道 | D7: =IFERROR(__xludf.DUMMYFUNCTION("""COMPUTED_VALUE"""),8363.0) -> 8363 | E7: =IFERROR(__xludf.DUMMYFUNCTION("""COMPUTED_VALUE"""),"ケーズデンキ 室蘭モルエ店") -> ケーズデンキ 室蘭モルエ店 | F7: =IFERROR(__xludf.DUMMYFUNCTION("""COMPUTED_VALUE"""),25.0) -> 25 | G7: =IFERROR(__xludf.DUMMYFUNCTION("""COMPUTED_VALUE"""),0.0) -> 0 | H7: =IFERROR(__xludf.DUMMYFUNCTION("""COMPUTED_VALUE"""),0.0) -> 0 | I7: =IFERROR(__xludf.DUMMYFUNCTION("""COMPUTED_VALUE"""),0.0) -> 0 | J7: =IFERROR(__xludf.DUMMYFUNCTION("""COMPUTED_VALUE"""),0.0) -> 0 | K7: =IFERROR(__xludf.DUMMYFUNCTION("""COMPUTED_VALUE"""),0.0) -> 0 | L7: =IFERROR(__xludf.DUMMYFUNCTION("""COMPUTED_VALUE"""),1.0) -> 1 | M7: =IFERROR(__xludf.DUMMYFUNCTION("""COMPUTED_VALUE"""),0.0) -> 0 | N7: =IFERROR(__xludf.DUMMYFUNCTION("""COMPUTED_VALUE"""),0.0) -> 0 | O7: =IFERROR(__xludf.DUMMYFUNCTION("""COMPUTED_VALUE"""),0.0) -> 0 | P7: =IFERROR(__xludf.DUMMYFUNCTION("""COMPUTED_VALUE"""),0.0) -> 0 | Q7: =IFERROR(__xludf.DUMMYFUNCTION("""COMPUTED_VALUE"""),0.0) -> 0 | R7: =IFERROR(__xludf.DUMMYFUNCTION("""COMPUTED_VALUE"""),1.0) -> 1 | S7: =IFERROR(__xludf.DUMMYFUNCTION("""COMPUTED_VALUE"""),25.0) -> 25 | T7: =IFERROR(__xludf.DUMMYFUNCTION("""COMPUTED_VALUE"""),25.0) -> 25 | U7: {=IF($D7="","",IFERROR(_xlfn.XLOOKUP($D7,'TIR店舗一覧'!$D:$D,'TIR店舗一覧'!$E:$E,""),""))} -> KS | V7: 0 | W7: 0 | X7: 0 | Y7: 0 | Z7: 0 | AA7: 25 | AB7: 0 | AC7: 0 | AD7: 0 | AE7: 0 | AF7: 0 | AG7: 25
B8: =IFERROR(__xludf.DUMMYFUNCTION("""COMPUTED_VALUE"""),46296.0) -> 46296 | C8: =IFERROR(__xludf.DUMMYFUNCTION("""COMPUTED_VALUE"""),"北海道") -> 北海道 | D8: =IFERROR(__xludf.DUMMYFUNCTION("""COMPUTED_VALUE"""),8326.0) -> 8326 | E8: =IFERROR(__xludf.DUMMYFUNCTION("""COMPUTED_VALUE"""),"ケーズデンキ 釧路本店") -> ケーズデンキ 釧路本店 | F8: =IFERROR(__xludf.DUMMYFUNCTION("""COMPUTED_VALUE"""),21.0) -> 21 | G8: =IFERROR(__xludf.DUMMYFUNCTION("""COMPUTED_VALUE"""),0.0) -> 0 | H8: =IFERROR(__xludf.DUMMYFUNCTION("""COMPUTED_VALUE"""),0.0) -> 0 | I8: =IFERROR(__xludf.DUMMYFUNCTION("""COMPUTED_VALUE"""),0.0) -> 0 | J8: =IFERROR(__xludf.DUMMYFUNCTION("""COMPUTED_VALUE"""),0.0) -> 0 | K8: =IFERROR(__xludf.DUMMYFUNCTION("""COMPUTED_VALUE"""),0.0) -> 0 | L8: =IFERROR(__xludf.DUMMYFUNCTION("""COMPUTED_VALUE"""),1.0) -> 1 | M8: =IFERROR(__xludf.DUMMYFUNCTION("""COMPUTED_VALUE"""),0.0) -> 0 | N8: =IFERROR(__xludf.DUMMYFUNCTION("""COMPUTED_VALUE"""),0.0) -> 0 | O8: =IFERROR(__xludf.DUMMYFUNCTION("""COMPUTED_VALUE"""),0.0) -> 0 | P8: =IFERROR(__xludf.DUMMYFUNCTION("""COMPUTED_VALUE"""),0.0) -> 0 | Q8: =IFERROR(__xludf.DUMMYFUNCTION("""COMPUTED_VALUE"""),0.0) -> 0 | R8: =IFERROR(__xludf.DUMMYFUNCTION("""COMPUTED_VALUE"""),1.0) -> 1 | S8: =IFERROR(__xludf.DUMMYFUNCTION("""COMPUTED_VALUE"""),21.0) -> 21 | T8: =IFERROR(__xludf.DUMMYFUNCTION("""COMPUTED_VALUE"""),21.0) -> 21 | U8: {=IF($D8="","",IFERROR(_xlfn.XLOOKUP($D8,'TIR店舗一覧'!$D:$D,'TIR店舗一覧'!$E:$E,""),""))} -> KS | V8: 0 | W8: 0 | X8: 0 | Y8: 0 | Z8: 0 | AA8: 21 | AB8: 0 | AC8: 0 | AD8: 0 | AE8: 0 | AF8: 0 | AG8: 21
B9: =IFERROR(__xludf.DUMMYFUNCTION("""COMPUTED_VALUE"""),46296.0) -> 46296 | C9: =IFERROR(__xludf.DUMMYFUNCTION("""COMPUTED_VALUE"""),"北海道") -> 北海道 | D9: =IFERROR(__xludf.DUMMYFUNCTION("""COMPUTED_VALUE"""),7071.0) -> 7071 | E9: =IFERROR(__xludf.DUMMYFUNCTION("""COMPUTED_VALUE"""),"ケーズデンキ インターヴィレッジ大曲店") -> ケーズデンキ インターヴィレッジ大曲店 | F9: =IFERROR(__xludf.DUMMYFUNCTION("""COMPUTED_VALUE"""),23.0) -> 23 | G9: =IFERROR(__xludf.DUMMYFUNCTION("""COMPUTED_VALUE"""),0.0) -> 0 | H9: =IFERROR(__xludf.DUMMYFUNCTION("""COMPUTED_VALUE"""),0.0) -> 0 | I9: =IFERROR(__xludf.DUMMYFUNCTION("""COMPUTED_VALUE"""),0.0) -> 0 | J9: =IFERROR(__xludf.DUMMYFUNCTION("""COMPUTED_VALUE"""),0.0) -> 0 | K9: =IFERROR(__xludf.DUMMYFUNCTION("""COMPUTED_VALUE"""),0.0) -> 0 | L9: =IFERROR(__xludf.DUMMYFUNCTION("""COMPUTED_VALUE"""),1.0) -> 1 | M9: =IFERROR(__xludf.DUMMYFUNCTION("""COMPUTED_VALUE"""),0.0) -> 0 | N9: =IFERROR(__xludf.DUMMYFUNCTION("""COMPUTED_VALUE"""),0.0) -> 0 | O9: =IFERROR(__xludf.DUMMYFUNCTION("""COMPUTED_VALUE"""),0.0) -> 0 | P9: =IFERROR(__xludf.DUMMYFUNCTION("""COMPUTED_VALUE"""),0.0) -> 0 | Q9: =IFERROR(__xludf.DUMMYFUNCTION("""COMPUTED_VALUE"""),0.0) -> 0 | R9: =IFERROR(__xludf.DUMMYFUNCTION("""COMPUTED_VALUE"""),1.0) -> 1 | S9: =IFERROR(__xludf.DUMMYFUNCTION("""COMPUTED_VALUE"""),23.0) -> 23 | T9: =IFERROR(__xludf.DUMMYFUNCTION("""COMPUTED_VALUE"""),23.0) -> 23 | U9: {=IF($D9="","",IFERROR(_xlfn.XLOOKUP($D9,'TIR店舗一覧'!$D:$D,'TIR店舗一覧'!$E:$E,""),""))} -> KS | V9: 0 | W9: 0 | X9: 0 | Y9: 0 | Z9: 0 | AA9: 23 | AB9: 0 | AC9: 0 | AD9: 0 | AE9: 0 | AF9: 0 | AG9: 23
B10: =IFERROR(__xludf.DUMMYFUNCTION("""COMPUTED_VALUE"""),46296.0) -> 46296 | C10: =IFERROR(__xludf.DUMMYFUNCTION("""COMPUTED_VALUE"""),"北海道") -> 北海道 | D10: =IFERROR(__xludf.DUMMYFUNCTION("""COMPUTED_VALUE"""),8903.0) -> 8903 | E10: =IFERROR(__xludf.DUMMYFUNCTION("""COMPUTED_VALUE"""),"エディオン 旭川豊岡店") -> エディオン 旭川豊岡店 | F10: =IFERROR(__xludf.DUMMYFUNCTION("""COMPUTED_VALUE"""),23.0) -> 23 | G10: =IFERROR(__xludf.DUMMYFUNCTION("""COMPUTED_VALUE"""),0.0) -> 0 | H10: =IFERROR(__xludf.DUMMYFUNCTION("""COMPUTED_VALUE"""),0.0) -> 0 | I10: =IFERROR(__xludf.DUMMYFUNCTION("""COMPUTED_VALUE"""),0.0) -> 0 | J10: =IFERROR(__xludf.DUMMYFUNCTION("""COMPUTED_VALUE"""),0.0) -> 0 | K10: =IFERROR(__xludf.DUMMYFUNCTION("""COMPUTED_VALUE"""),0.0) -> 0 | L10: =IFERROR(__xludf.DUMMYFUNCTION("""COMPUTED_VALUE"""),1.0) -> 1 | M10: =IFERROR(__xludf.DUMMYFUNCTION("""COMPUTED_VALUE"""),0.0) -> 0 | N10: =IFERROR(__xludf.DUMMYFUNCTION("""COMPUTED_VALUE"""),0.0) -> 0 | O10: =IFERROR(__xludf.DUMMYFUNCTION("""COMPUTED_VALUE"""),0.0) -> 0 | P10: =IFERROR(__xludf.DUMMYFUNCTION("""COMPUTED_VALUE"""),0.0) -> 0 | Q10: =IFERROR(__xludf.DUMMYFUNCTION("""COMPUTED_VALUE"""),0.0) -> 0 | R10: =IFERROR(__xludf.DUMMYFUNCTION("""COMPUTED_VALUE"""),1.0) -> 1 | S10: =IFERROR(__xludf.DUMMYFUNCTION("""COMPUTED_VALUE"""),23.0) -> 23 | T10: =IFERROR(__xludf.DUMMYFUNCTION("""COMPUTED_VALUE"""),23.0) -> 23 | U10: {=IF($D10="","",IFERROR(_xlfn.XLOOKUP($D10,'TIR店舗一覧'!$D:$D,'TIR店舗一覧'!$E:$E,""),""))} -> ED | V10: 0 | W10: 0 | X10: 0 | Y10: 0 | Z10: 0 | AA10: 23 | AB10: 0 | AC10: 0 | AD10: 0 | AE10: 0 | AF10: 0 | AG10: 23
B11: =IFERROR(__xludf.DUMMYFUNCTION("""COMPUTED_VALUE"""),46296.0) -> 46296 | C11: =IFERROR(__xludf.DUMMYFUNCTION("""COMPUTED_VALUE"""),"関東") -> 関東 | D11: =IFERROR(__xludf.DUMMYFUNCTION("""COMPUTED_VALUE"""),8991.0) -> 8991 | E11: =IFERROR(__xludf.DUMMYFUNCTION("""COMPUTED_VALUE"""),"ヤマダファミリーショップ ヤオ秩父店") -> ヤマダファミリーショップ ヤオ秩父店 | F11: =IFERROR(__xludf.DUMMYFUNCTION("""COMPUTED_VALUE"""),40.0) -> 40 | G11: =IFERROR(__xludf.DUMMYFUNCTION("""COMPUTED_VALUE"""),0.0) -> 0 | H11: =IFERROR(__xludf.DUMMYFUNCTION("""COMPUTED_VALUE"""),0.0) -> 0 | I11: =IFERROR(__xludf.DUMMYFUNCTION("""COMPUTED_VALUE"""),0.0) -> 0 | J11: =IFERROR(__xludf.DUMMYFUNCTION("""COMPUTED_VALUE"""),0.0) -> 0 | K11: =IFERROR(__xludf.DUMMYFUNCTION("""COMPUTED_VALUE"""),0.0) -> 0 | L11: =IFERROR(__xludf.DUMMYFUNCTION("""COMPUTED_VALUE"""),1.0) -> 1 | M11: =IFERROR(__xludf.DUMMYFUNCTION("""COMPUTED_VALUE"""),0.0) -> 0 | N11: =IFERROR(__xludf.DUMMYFUNCTION("""COMPUTED_VALUE"""),0.0) -> 0 | O11: =IFERROR(__xludf.DUMMYFUNCTION("""COMPUTED_VALUE"""),0.0) -> 0 | P11: =IFERROR(__xludf.DUMMYFUNCTION("""COMPUTED_VALUE"""),0.0) -> 0 | Q11: =IFERROR(__xludf.DUMMYFUNCTION("""COMPUTED_VALUE"""),0.0) -> 0 | R11: =IFERROR(__xludf.DUMMYFUNCTION("""COMPUTED_VALUE"""),1.0) -> 1 | S11: =IFERROR(__xludf.DUMMYFUNCTION("""COMPUTED_VALUE"""),40.0) -> 40 | T11: =IFERROR(__xludf.DUMMYFUNCTION("""COMPUTED_VALUE"""),40.0) -> 40 | U11: {=IF($D11="","",IFERROR(_xlfn.XLOOKUP($D11,'TIR店舗一覧'!$D:$D,'TIR店舗一覧'!$E:$E,""),""))} -> YD | V11: 0 | W11: 0 | X11: 0 | Y11: 0 | Z11: 0 | AA11: 40 | AB11: 0 | AC11: 0 | AD11: 0 | AE11: 0 | AF11: 0 | AG11: 40
B12: =IFERROR(__xludf.DUMMYFUNCTION("""COMPUTED_VALUE"""),46296.0) -> 46296 | C12: =IFERROR(__xludf.DUMMYFUNCTION("""COMPUTED_VALUE"""),"関東") -> 関東 | D12: =IFERROR(__xludf.DUMMYFUNCTION("""COMPUTED_VALUE"""),8655.0) -> 8655 | E12: =IFERROR(__xludf.DUMMYFUNCTION("""COMPUTED_VALUE"""),"テックランド厚木店") -> テックランド厚木店 | F12: =IFERROR(__xludf.DUMMYFUNCTION("""COMPUTED_VALUE"""),19.0) -> 19 | G12: =IFERROR(__xludf.DUMMYFUNCTION("""COMPUTED_VALUE"""),0.0) -> 0 | H12: =IFERROR(__xludf.DUMMYFUNCTION("""COMPUTED_VALUE"""),0.0) -> 0 | I12: =IFERROR(__xludf.DUMMYFUNCTION("""COMPUTED_VALUE"""),0.0) -> 0 | J12: =IFERROR(__xludf.DUMMYFUNCTION("""COMPUTED_VALUE"""),0.0) -> 0 | K12: =IFERROR(__xludf.DUMMYFUNCTION("""COMPUTED_VALUE"""),0.0) -> 0 | L12: =IFERROR(__xludf.DUMMYFUNCTION("""COMPUTED_VALUE"""),1.0) -> 1 | M12: =IFERROR(__xludf.DUMMYFUNCTION("""COMPUTED_VALUE"""),0.0) -> 0 | N12: =IFERROR(__xludf.DUMMYFUNCTION("""COMPUTED_VALUE"""),0.0) -> 0 | O12: =IFERROR(__xludf.DUMMYFUNCTION("""COMPUTED_VALUE"""),0.0) -> 0 | P12: =IFERROR(__xludf.DUMMYFUNCTION("""COMPUTED_VALUE"""),0.0) -> 0 | Q12: =IFERROR(__xludf.DUMMYFUNCTION("""COMPUTED_VALUE"""),0.0) -> 0 | R12: =IFERROR(__xludf.DUMMYFUNCTION("""COMPUTED_VALUE"""),1.0) -> 1 | S12: =IFERROR(__xludf.DUMMYFUNCTION("""COMPUTED_VALUE"""),19.0) -> 19 | T12: =IFERROR(__xludf.DUMMYFUNCTION("""COMPUTED_VALUE"""),19.0) -> 19 | U12: {=IF($D12="","",IFERROR(_xlfn.XLOOKUP($D12,'TIR店舗一覧'!$D:$D,'TIR店舗一覧'!$E:$E,""),""))} -> YD | V12: 0 | W12: 0 | X12: 0 | Y12: 0 | Z12: 0 | AA12: 19 | AB12: 0 | AC12: 0 | AD12: 0 | AE12: 0 | AF12: 0 | AG12: 19
B13: =IFERROR(__xludf.DUMMYFUNCTION("""COMPUTED_VALUE"""),46296.0) -> 46296 | C13: =IFERROR(__xludf.DUMMYFUNCTION("""COMPUTED_VALUE"""),"関東") -> 関東 | D13: =IFERROR(__xludf.DUMMYFUNCTION("""COMPUTED_VALUE"""),8861.0) -> 8861 | E13: =IFERROR(__xludf.DUMMYFUNCTION("""COMPUTED_VALUE"""),"テックランド古河店") -> テックランド古河店 | F13: =IFERROR(__xludf.DUMMYFUNCTION("""COMPUTED_VALUE"""),18.0) -> 18 | G13: =IFERROR(__xludf.DUMMYFUNCTION("""COMPUTED_VALUE"""),0.0) -> 0 | H13: =IFERROR(__xludf.DUMMYFUNCTION("""COMPUTED_VALUE"""),0.0) -> 0 | I13: =IFERROR(__xludf.DUMMYFUNCTION("""COMPUTED_VALUE"""),0.0) -> 0 | J13: =IFERROR(__xludf.DUMMYFUNCTION("""COMPUTED_VALUE"""),0.0) -> 0 | K13: =IFERROR(__xludf.DUMMYFUNCTION("""COMPUTED_VALUE"""),0.0) -> 0 | L13: =IFERROR(__xludf.DUMMYFUNCTION("""COMPUTED_VALUE"""),1.0) -> 1 | M13: =IFERROR(__xludf.DUMMYFUNCTION("""COMPUTED_VALUE"""),0.0) -> 0 | N13: =IFERROR(__xludf.DUMMYFUNCTION("""COMPUTED_VALUE"""),0.0) -> 0 | O13: =IFERROR(__xludf.DUMMYFUNCTION("""COMPUTED_VALUE"""),0.0) -> 0 | P13: =IFERROR(__xludf.DUMMYFUNCTION("""COMPUTED_VALUE"""),0.0) -> 0 | Q13: =IFERROR(__xludf.DUMMYFUNCTION("""COMPUTED_VALUE"""),0.0) -> 0 | R13: =IFERROR(__xludf.DUMMYFUNCTION("""COMPUTED_VALUE"""),1.0) -> 1 | S13: =IFERROR(__xludf.DUMMYFUNCTION("""COMPUTED_VALUE"""),18.0) -> 18 | T13: =IFERROR(__xludf.DUMMYFUNCTION("""COMPUTED_VALUE"""),18.0) -> 18 | U13: {=IF($D13="","",IFERROR(_xlfn.XLOOKUP($D13,'TIR店舗一覧'!$D:$D,'TIR店舗一覧'!$E:$E,""),""))} -> YD | V13: 0 | W13: 0 | X13: 0 | Y13: 0 | Z13: 0 | AA13: 18 | AB13: 0 | AC13: 0 | AD13: 0 | AE13: 0 | AF13: 0 | AG13: 18
B14: =IFERROR(__xludf.DUMMYFUNCTION("""COMPUTED_VALUE"""),46296.0) -> 46296 | C14: =IFERROR(__xludf.DUMMYFUNCTION("""COMPUTED_VALUE"""),"関東") -> 関東 | D14: =IFERROR(__xludf.DUMMYFUNCTION("""COMPUTED_VALUE"""),7691.0) -> 7691 | E14: =IFERROR(__xludf.DUMMYFUNCTION("""COMPUTED_VALUE"""),"テックランド横浜泉店") -> テックランド横浜泉店 | F14: =IFERROR(__xludf.DUMMYFUNCTION("""COMPUTED_VALUE"""),11.0) -> 11 | G14: =IFERROR(__xludf.DUMMYFUNCTION("""COMPUTED_VALUE"""),0.0) -> 0 | H14: =IFERROR(__xludf.DUMMYFUNCTION("""COMPUTED_VALUE"""),0.0) -> 0 | I14: =IFERROR(__xludf.DUMMYFUNCTION("""COMPUTED_VALUE"""),0.0) -> 0 | J14: =IFERROR(__xludf.DUMMYFUNCTION("""COMPUTED_VALUE"""),0.0) -> 0 | K14: =IFERROR(__xludf.DUMMYFUNCTION("""COMPUTED_VALUE"""),0.0) -> 0 | L14: =IFERROR(__xludf.DUMMYFUNCTION("""COMPUTED_VALUE"""),1.0) -> 1 | M14: =IFERROR(__xludf.DUMMYFUNCTION("""COMPUTED_VALUE"""),0.0) -> 0 | N14: =IFERROR(__xludf.DUMMYFUNCTION("""COMPUTED_VALUE"""),0.0) -> 0 | O14: =IFERROR(__xludf.DUMMYFUNCTION("""COMPUTED_VALUE"""),0.0) -> 0 | P14: =IFERROR(__xludf.DUMMYFUNCTION("""COMPUTED_VALUE"""),0.0) -> 0 | Q14: =IFERROR(__xludf.DUMMYFUNCTION("""COMPUTED_VALUE"""),0.0) -> 0 | R14: =IFERROR(__xludf.DUMMYFUNCTION("""COMPUTED_VALUE"""),1.0) -> 1 | S14: =IFERROR(__xludf.DUMMYFUNCTION("""COMPUTED_VALUE"""),11.0) -> 11 | T14: =IFERROR(__xludf.DUMMYFUNCTION("""COMPUTED_VALUE"""),11.0) -> 11 | U14: {=IF($D14="","",IFERROR(_xlfn.XLOOKUP($D14,'TIR店舗一覧'!$D:$D,'TIR店舗一覧'!$E:$E,""),""))} -> YD | V14: 0 | W14: 0 | X14: 0 | Y14: 0 | Z14: 0 | AA14: 11 | AB14: 0 | AC14: 0 | AD14: 0 | AE14: 0 | AF14: 0 | AG14: 11
B15: =IFERROR(__xludf.DUMMYFUNCTION("""COMPUTED_VALUE"""),46296.0) -> 46296 | C15: =IFERROR(__xludf.DUMMYFUNCTION("""COMPUTED_VALUE"""),"関東") -> 関東 | D15: =IFERROR(__xludf.DUMMYFUNCTION("""COMPUTED_VALUE"""),1026.0) -> 1026 | E15: =IFERROR(__xludf.DUMMYFUNCTION("""COMPUTED_VALUE"""),"テックランドイオンモール小山店") -> テックランドイオンモール小山店 | F15: =IFERROR(__xludf.DUMMYFUNCTION("""COMPUTED_VALUE"""),0.0) -> 0 | G15: =IFERROR(__xludf.DUMMYFUNCTION("""COMPUTED_VALUE"""),"-") -> - | H15: =IFERROR(__xludf.DUMMYFUNCTION("""COMPUTED_VALUE"""),"-") -> - | I15: =IFERROR(__xludf.DUMMYFUNCTION("""COMPUTED_VALUE"""),"-") -> - | J15: =IFERROR(__xludf.DUMMYFUNCTION("""COMPUTED_VALUE"""),"-") -> - | K15: =IFERROR(__xludf.DUMMYFUNCTION("""COMPUTED_VALUE"""),"-") -> - | L15: =IFERROR(__xludf.DUMMYFUNCTION("""COMPUTED_VALUE"""),"-") -> - | M15: =IFERROR(__xludf.DUMMYFUNCTION("""COMPUTED_VALUE"""),"-") -> - | N15: =IFERROR(__xludf.DUMMYFUNCTION("""COMPUTED_VALUE"""),"-") -> - | ... R15: =IFERROR(__xludf.DUMMYFUNCTION("""COMPUTED_VALUE"""),"-") -> - | S15: =IFERROR(__xludf.DUMMYFUNCTION("""COMPUTED_VALUE"""),0.0) -> 0 | T15: =IFERROR(__xludf.DUMMYFUNCTION("""COMPUTED_VALUE"""),0.0) -> 0 | U15: {=IF($D15="","",IFERROR(_xlfn.XLOOKUP($D15,'TIR店舗一覧'!$D:$D,'TIR店舗一覧'!$E:$E,""),""))} -> YD | V15: 0 | W15: 0 | X15: 0 | Y15: 0 | Z15: 0 | AA15: 0 | AB15: 0 | AC15: 0 | AD15: 0 | AE15: 0 | AF15: 0 | AG15: 0
B16: =IFERROR(__xludf.DUMMYFUNCTION("""COMPUTED_VALUE"""),46296.0) -> 46296 | C16: =IFERROR(__xludf.DUMMYFUNCTION("""COMPUTED_VALUE"""),"関東") -> 関東 | D16: =IFERROR(__xludf.DUMMYFUNCTION("""COMPUTED_VALUE"""),8626.0) -> 8626 | E16: =IFERROR(__xludf.DUMMYFUNCTION("""COMPUTED_VALUE"""),"テックランド 横須賀店") -> テックランド 横須賀店 | F16: =IFERROR(__xludf.DUMMYFUNCTION("""COMPUTED_VALUE"""),17.0) -> 17 | G16: =IFERROR(__xludf.DUMMYFUNCTION("""COMPUTED_VALUE"""),0.0) -> 0 | H16: =IFERROR(__xludf.DUMMYFUNCTION("""COMPUTED_VALUE"""),0.0) -> 0 | I16: =IFERROR(__xludf.DUMMYFUNCTION("""COMPUTED_VALUE"""),0.0) -> 0 | J16: =IFERROR(__xludf.DUMMYFUNCTION("""COMPUTED_VALUE"""),0.0) -> 0 | K16: =IFERROR(__xludf.DUMMYFUNCTION("""COMPUTED_VALUE"""),0.0) -> 0 | L16: =IFERROR(__xludf.DUMMYFUNCTION("""COMPUTED_VALUE"""),1.0) -> 1 | M16: =IFERROR(__xludf.DUMMYFUNCTION("""COMPUTED_VALUE"""),0.0) -> 0 | N16: =IFERROR(__xludf.DUMMYFUNCTION("""COMPUTED_VALUE"""),0.0) -> 0 | O16: =IFERROR(__xludf.DUMMYFUNCTION("""COMPUTED_VALUE"""),0.0) -> 0 | P16: =IFERROR(__xludf.DUMMYFUNCTION("""COMPUTED_VALUE"""),0.0) -> 0 | Q16: =IFERROR(__xludf.DUMMYFUNCTION("""COMPUTED_VALUE"""),0.0) -> 0 | R16: =IFERROR(__xludf.DUMMYFUNCTION("""COMPUTED_VALUE"""),1.0) -> 1 | S16: =IFERROR(__xludf.DUMMYFUNCTION("""COMPUTED_VALUE"""),17.0) -> 17 | T16: =IFERROR(__xludf.DUMMYFUNCTION("""COMPUTED_VALUE"""),17.0) -> 17 | U16: {=IF($D16="","",IFERROR(_xlfn.XLOOKUP($D16,'TIR店舗一覧'!$D:$D,'TIR店舗一覧'!$E:$E,""),""))} -> YD | V16: 0 | W16: 0 | X16: 0 | Y16: 0 | Z16: 0 | AA16: 17 | AB16: 0 | AC16: 0 | AD16: 0 | AE16: 0 | AF16: 0 | AG16: 17
B17: =IFERROR(__xludf.DUMMYFUNCTION("""COMPUTED_VALUE"""),46296.0) -> 46296 | C17: =IFERROR(__xludf.DUMMYFUNCTION("""COMPUTED_VALUE"""),"関東") -> 関東 | D17: =IFERROR(__xludf.DUMMYFUNCTION("""COMPUTED_VALUE"""),8855.0) -> 8855 | E17: =IFERROR(__xludf.DUMMYFUNCTION("""COMPUTED_VALUE"""),"テックランド 宇都宮インターパーク店") -> テックランド 宇都宮インターパーク店 | F17: =IFERROR(__xludf.DUMMYFUNCTION("""COMPUTED_VALUE"""),11.0) -> 11 | G17: =IFERROR(__xludf.DUMMYFUNCTION("""COMPUTED_VALUE"""),0.0) -> 0 | H17: =IFERROR(__xludf.DUMMYFUNCTION("""COMPUTED_VALUE"""),0.0) -> 0 | I17: =IFERROR(__xludf.DUMMYFUNCTION("""COMPUTED_VALUE"""),0.0) -> 0 | J17: =IFERROR(__xludf.DUMMYFUNCTION("""COMPUTED_VALUE"""),0.0) -> 0 | K17: =IFERROR(__xludf.DUMMYFUNCTION("""COMPUTED_VALUE"""),0.0) -> 0 | L17: =IFERROR(__xludf.DUMMYFUNCTION("""COMPUTED_VALUE"""),1.0) -> 1 | M17: =IFERROR(__xludf.DUMMYFUNCTION("""COMPUTED_VALUE"""),0.0) -> 0 | N17: =IFERROR(__xludf.DUMMYFUNCTION("""COMPUTED_VALUE"""),0.0) -> 0 | O17: =IFERROR(__xludf.DUMMYFUNCTION("""COMPUTED_VALUE"""),0.0) -> 0 | P17: =IFERROR(__xludf.DUMMYFUNCTION("""COMPUTED_VALUE"""),0.0) -> 0 | Q17: =IFERROR(__xludf.DUMMYFUNCTION("""COMPUTED_VALUE"""),0.0) -> 0 | R17: =IFERROR(__xludf.DUMMYFUNCTION("""COMPUTED_VALUE"""),1.0) -> 1 | S17: =IFERROR(__xludf.DUMMYFUNCTION("""COMPUTED_VALUE"""),11.0) -> 11 | T17: =IFERROR(__xludf.DUMMYFUNCTION("""COMPUTED_VALUE"""),11.0) -> 11 | U17: {=IF($D17="","",IFERROR(_xlfn.XLOOKUP($D17,'TIR店舗一覧'!$D:$D,'TIR店舗一覧'!$E:$E,""),""))} -> YD | V17: 0 | W17: 0 | X17: 0 | Y17: 0 | Z17: 0 | AA17: 11 | AB17: 0 | AC17: 0 | AD17: 0 | AE17: 0 | AF17: 0 | AG17: 11
B18: =IFERROR(__xludf.DUMMYFUNCTION("""COMPUTED_VALUE"""),46296.0) -> 46296 | C18: =IFERROR(__xludf.DUMMYFUNCTION("""COMPUTED_VALUE"""),"関東") -> 関東 | D18: =IFERROR(__xludf.DUMMYFUNCTION("""COMPUTED_VALUE"""),8956.0) -> 8956 | E18: =IFERROR(__xludf.DUMMYFUNCTION("""COMPUTED_VALUE"""),"ケーズデンキ 君津店") -> ケーズデンキ 君津店 | F18: =IFERROR(__xludf.DUMMYFUNCTION("""COMPUTED_VALUE"""),6.0) -> 6 | G18: =IFERROR(__xludf.DUMMYFUNCTION("""COMPUTED_VALUE"""),0.0) -> 0 | H18: =IFERROR(__xludf.DUMMYFUNCTION("""COMPUTED_VALUE"""),0.0) -> 0 | I18: =IFERROR(__xludf.DUMMYFUNCTION("""COMPUTED_VALUE"""),0.0) -> 0 | J18: =IFERROR(__xludf.DUMMYFUNCTION("""COMPUTED_VALUE"""),0.0) -> 0 | K18: =IFERROR(__xludf.DUMMYFUNCTION("""COMPUTED_VALUE"""),0.0) -> 0 | L18: =IFERROR(__xludf.DUMMYFUNCTION("""COMPUTED_VALUE"""),1.0) -> 1 | M18: =IFERROR(__xludf.DUMMYFUNCTION("""COMPUTED_VALUE"""),0.0) -> 0 | N18: =IFERROR(__xludf.DUMMYFUNCTION("""COMPUTED_VALUE"""),0.0) -> 0 | O18: =IFERROR(__xludf.DUMMYFUNCTION("""COMPUTED_VALUE"""),0.0) -> 0 | P18: =IFERROR(__xludf.DUMMYFUNCTION("""COMPUTED_VALUE"""),0.0) -> 0 | Q18: =IFERROR(__xludf.DUMMYFUNCTION("""COMPUTED_VALUE"""),0.0) -> 0 | R18: =IFERROR(__xludf.DUMMYFUNCTION("""COMPUTED_VALUE"""),1.0) -> 1 | S18: =IFERROR(__xludf.DUMMYFUNCTION("""COMPUTED_VALUE"""),6.0) -> 6 | T18: =IFERROR(__xludf.DUMMYFUNCTION("""COMPUTED_VALUE"""),6.0) -> 6 | U18: {=IF($D18="","",IFERROR(_xlfn.XLOOKUP($D18,'TIR店舗一覧'!$D:$D,'TIR店舗一覧'!$E:$E,""),""))} -> KS | V18: 0 | W18: 0 | X18: 0 | Y18: 0 | Z18: 0 | AA18: 6 | AB18: 0 | AC18: 0 | AD18: 0 | AE18: 0 | AF18: 0 | AG18: 6
B19: =IFERROR(__xludf.DUMMYFUNCTION("""COMPUTED_VALUE"""),46296.0) -> 46296 | C19: =IFERROR(__xludf.DUMMYFUNCTION("""COMPUTED_VALUE"""),"関東") -> 関東 | D19: =IFERROR(__xludf.DUMMYFUNCTION("""COMPUTED_VALUE"""),7671.0) -> 7671 | E19: =IFERROR(__xludf.DUMMYFUNCTION("""COMPUTED_VALUE"""),"Tecc LIFE SELECT 港北センター店") -> Tecc LIFE SELECT 港北センター店 | F19: =IFERROR(__xludf.DUMMYFUNCTION("""COMPUTED_VALUE"""),15.0) -> 15 | G19: =IFERROR(__xludf.DUMMYFUNCTION("""COMPUTED_VALUE"""),0.0) -> 0 | H19: =IFERROR(__xludf.DUMMYFUNCTION("""COMPUTED_VALUE"""),0.0) -> 0 | I19: =IFERROR(__xludf.DUMMYFUNCTION("""COMPUTED_VALUE"""),0.0) -> 0 | J19: =IFERROR(__xludf.DUMMYFUNCTION("""COMPUTED_VALUE"""),0.0) -> 0 | K19: =IFERROR(__xludf.DUMMYFUNCTION("""COMPUTED_VALUE"""),0.0) -> 0 | L19: =IFERROR(__xludf.DUMMYFUNCTION("""COMPUTED_VALUE"""),1.0) -> 1 | M19: =IFERROR(__xludf.DUMMYFUNCTION("""COMPUTED_VALUE"""),0.0) -> 0 | N19: =IFERROR(__xludf.DUMMYFUNCTION("""COMPUTED_VALUE"""),0.0) -> 0 | O19: =IFERROR(__xludf.DUMMYFUNCTION("""COMPUTED_VALUE"""),0.0) -> 0 | P19: =IFERROR(__xludf.DUMMYFUNCTION("""COMPUTED_VALUE"""),0.0) -> 0 | Q19: =IFERROR(__xludf.DUMMYFUNCTION("""COMPUTED_VALUE"""),0.0) -> 0 | R19: =IFERROR(__xludf.DUMMYFUNCTION("""COMPUTED_VALUE"""),1.0) -> 1 | S19: =IFERROR(__xludf.DUMMYFUNCTION("""COMPUTED_VALUE"""),15.0) -> 15 | T19: =IFERROR(__xludf.DUMMYFUNCTION("""COMPUTED_VALUE"""),15.0) -> 15 | U19: {=IF($D19="","",IFERROR(_xlfn.XLOOKUP($D19,'TIR店舗一覧'!$D:$D,'TIR店舗一覧'!$E:$E,""),""))} -> YD | V19: 0 | W19: 0 | X19: 0 | Y19: 0 | Z19: 0 | AA19: 15 | AB19: 0 | AC19: 0 | AD19: 0 | AE19: 0 | AF19: 0 | AG19: 15
B20: =IFERROR(__xludf.DUMMYFUNCTION("""COMPUTED_VALUE"""),46296.0) -> 46296 | C20: =IFERROR(__xludf.DUMMYFUNCTION("""COMPUTED_VALUE"""),"関東") -> 関東 | D20: =IFERROR(__xludf.DUMMYFUNCTION("""COMPUTED_VALUE"""),8848.0) -> 8848 | E20: =IFERROR(__xludf.DUMMYFUNCTION("""COMPUTED_VALUE"""),"Tecc LIFE SELECT ムサシ久喜菖蒲店") -> Tecc LIFE SELECT ムサシ久喜菖蒲店 | F20: =IFERROR(__xludf.DUMMYFUNCTION("""COMPUTED_VALUE"""),5.0) -> 5 | G20: =IFERROR(__xludf.DUMMYFUNCTION("""COMPUTED_VALUE"""),0.0) -> 0 | H20: =IFERROR(__xludf.DUMMYFUNCTION("""COMPUTED_VALUE"""),0.0) -> 0 | I20: =IFERROR(__xludf.DUMMYFUNCTION("""COMPUTED_VALUE"""),0.0) -> 0 | J20: =IFERROR(__xludf.DUMMYFUNCTION("""COMPUTED_VALUE"""),0.0) -> 0 | K20: =IFERROR(__xludf.DUMMYFUNCTION("""COMPUTED_VALUE"""),0.0) -> 0 | L20: =IFERROR(__xludf.DUMMYFUNCTION("""COMPUTED_VALUE"""),1.0) -> 1 | M20: =IFERROR(__xludf.DUMMYFUNCTION("""COMPUTED_VALUE"""),0.0) -> 0 | N20: =IFERROR(__xludf.DUMMYFUNCTION("""COMPUTED_VALUE"""),0.0) -> 0 | O20: =IFERROR(__xludf.DUMMYFUNCTION("""COMPUTED_VALUE"""),0.0) -> 0 | P20: =IFERROR(__xludf.DUMMYFUNCTION("""COMPUTED_VALUE"""),0.0) -> 0 | Q20: =IFERROR(__xludf.DUMMYFUNCTION("""COMPUTED_VALUE"""),0.0) -> 0 | R20: =IFERROR(__xludf.DUMMYFUNCTION("""COMPUTED_VALUE"""),1.0) -> 1 | S20: =IFERROR(__xludf.DUMMYFUNCTION("""COMPUTED_VALUE"""),5.0) -> 5 | T20: =IFERROR(__xludf.DUMMYFUNCTION("""COMPUTED_VALUE"""),5.0) -> 5 | U20: {=IF($D20="","",IFERROR(_xlfn.XLOOKUP($D20,'TIR店舗一覧'!$D:$D,'TIR店舗一覧'!$E:$E,""),""))} -> YD | V20: 0 | W20: 0 | X20: 0 | Y20: 0 | Z20: 0 | AA20: 5 | AB20: 0 | AC20: 0 | AD20: 0 | AE20: 0 | AF20: 0 | AG20: 5
B21: =IFERROR(__xludf.DUMMYFUNCTION("""COMPUTED_VALUE"""),46296.0) -> 46296 | C21: =IFERROR(__xludf.DUMMYFUNCTION("""COMPUTED_VALUE"""),"信越") -> 信越 | D21: =IFERROR(__xludf.DUMMYFUNCTION("""COMPUTED_VALUE"""),8424.0) -> 8424 | E21: =IFERROR(__xludf.DUMMYFUNCTION("""COMPUTED_VALUE"""),"テックランド 新潟錦町本店") -> テックランド 新潟錦町本店 | F21: =IFERROR(__xludf.DUMMYFUNCTION("""COMPUTED_VALUE"""),14.0) -> 14 | G21: =IFERROR(__xludf.DUMMYFUNCTION("""COMPUTED_VALUE"""),0.0) -> 0 | H21: =IFERROR(__xludf.DUMMYFUNCTION("""COMPUTED_VALUE"""),0.0) -> 0 | I21: =IFERROR(__xludf.DUMMYFUNCTION("""COMPUTED_VALUE"""),0.0) -> 0 | J21: =IFERROR(__xludf.DUMMYFUNCTION("""COMPUTED_VALUE"""),0.0) -> 0 | K21: =IFERROR(__xludf.DUMMYFUNCTION("""COMPUTED_VALUE"""),0.0) -> 0 | L21: =IFERROR(__xludf.DUMMYFUNCTION("""COMPUTED_VALUE"""),1.0) -> 1 | M21: =IFERROR(__xludf.DUMMYFUNCTION("""COMPUTED_VALUE"""),0.0) -> 0 | N21: =IFERROR(__xludf.DUMMYFUNCTION("""COMPUTED_VALUE"""),0.0) -> 0 | O21: =IFERROR(__xludf.DUMMYFUNCTION("""COMPUTED_VALUE"""),0.0) -> 0 | P21: =IFERROR(__xludf.DUMMYFUNCTION("""COMPUTED_VALUE"""),0.0) -> 0 | Q21: =IFERROR(__xludf.DUMMYFUNCTION("""COMPUTED_VALUE"""),0.0) -> 0 | R21: =IFERROR(__xludf.DUMMYFUNCTION("""COMPUTED_VALUE"""),1.0) -> 1 | S21: =IFERROR(__xludf.DUMMYFUNCTION("""COMPUTED_VALUE"""),14.0) -> 14 | T21: =IFERROR(__xludf.DUMMYFUNCTION("""COMPUTED_VALUE"""),14.0) -> 14 | U21: {=IF($D21="","",IFERROR(_xlfn.XLOOKUP($D21,'TIR店舗一覧'!$D:$D,'TIR店舗一覧'!$E:$E,""),""))} -> YD | V21: 0 | W21: 0 | X21: 0 | Y21: 0 | Z21: 0 | AA21: 14 | AB21: 0 | AC21: 0 | AD21: 0 | AE21: 0 | AF21: 0 | AG21: 14
B22: =IFERROR(__xludf.DUMMYFUNCTION("""COMPUTED_VALUE"""),46296.0) -> 46296 | C22: =IFERROR(__xludf.DUMMYFUNCTION("""COMPUTED_VALUE"""),"信越") -> 信越 | D22: =IFERROR(__xludf.DUMMYFUNCTION("""COMPUTED_VALUE"""),8453.0) -> 8453 | E22: =IFERROR(__xludf.DUMMYFUNCTION("""COMPUTED_VALUE"""),"テックランド 亀田店") -> テックランド 亀田店 | F22: =IFERROR(__xludf.DUMMYFUNCTION("""COMPUTED_VALUE"""),23.0) -> 23 | G22: =IFERROR(__xludf.DUMMYFUNCTION("""COMPUTED_VALUE"""),0.0) -> 0 | H22: =IFERROR(__xludf.DUMMYFUNCTION("""COMPUTED_VALUE"""),0.0) -> 0 | I22: =IFERROR(__xludf.DUMMYFUNCTION("""COMPUTED_VALUE"""),0.0) -> 0 | J22: =IFERROR(__xludf.DUMMYFUNCTION("""COMPUTED_VALUE"""),0.0) -> 0 | K22: =IFERROR(__xludf.DUMMYFUNCTION("""COMPUTED_VALUE"""),0.0) -> 0 | L22: =IFERROR(__xludf.DUMMYFUNCTION("""COMPUTED_VALUE"""),1.0) -> 1 | M22: =IFERROR(__xludf.DUMMYFUNCTION("""COMPUTED_VALUE"""),0.0) -> 0 | N22: =IFERROR(__xludf.DUMMYFUNCTION("""COMPUTED_VALUE"""),0.0) -> 0 | O22: =IFERROR(__xludf.DUMMYFUNCTION("""COMPUTED_VALUE"""),0.0) -> 0 | P22: =IFERROR(__xludf.DUMMYFUNCTION("""COMPUTED_VALUE"""),0.0) -> 0 | Q22: =IFERROR(__xludf.DUMMYFUNCTION("""COMPUTED_VALUE"""),0.0) -> 0 | R22: =IFERROR(__xludf.DUMMYFUNCTION("""COMPUTED_VALUE"""),1.0) -> 1 | S22: =IFERROR(__xludf.DUMMYFUNCTION("""COMPUTED_VALUE"""),23.0) -> 23 | T22: =IFERROR(__xludf.DUMMYFUNCTION("""COMPUTED_VALUE"""),23.0) -> 23 | U22: {=IF($D22="","",IFERROR(_xlfn.XLOOKUP($D22,'TIR店舗一覧'!$D:$D,'TIR店舗一覧'!$E:$E,""),""))} -> YD | V22: 0 | W22: 0 | X22: 0 | Y22: 0 | Z22: 0 | AA22: 23 | AB22: 0 | AC22: 0 | AD22: 0 | AE22: 0 | AF22: 0 | AG22: 23
B23: =IFERROR(__xludf.DUMMYFUNCTION("""COMPUTED_VALUE"""),46296.0) -> 46296 | C23: =IFERROR(__xludf.DUMMYFUNCTION("""COMPUTED_VALUE"""),"信越") -> 信越 | D23: =IFERROR(__xludf.DUMMYFUNCTION("""COMPUTED_VALUE"""),8924.0) -> 8924 | E23: =IFERROR(__xludf.DUMMYFUNCTION("""COMPUTED_VALUE"""),"テックランド そよら三条須頃店") -> テックランド そよら三条須頃店 | F23: =IFERROR(__xludf.DUMMYFUNCTION("""COMPUTED_VALUE"""),15.0) -> 15 | G23: =IFERROR(__xludf.DUMMYFUNCTION("""COMPUTED_VALUE"""),0.40569395017793597) -> 0.40569395 | H23: =IFERROR(__xludf.DUMMYFUNCTION("""COMPUTED_VALUE"""),0.1103202846975089) -> 0.11032028 | I23: =IFERROR(__xludf.DUMMYFUNCTION("""COMPUTED_VALUE"""),0.13167259786476868) -> 0.1316726 | J23: =IFERROR(__xludf.DUMMYFUNCTION("""COMPUTED_VALUE"""),0.1708185053380783) -> 0.17081851 | K23: =IFERROR(__xludf.DUMMYFUNCTION("""COMPUTED_VALUE"""),0.12811387900355872) -> 0.12811388 | L23: =IFERROR(__xludf.DUMMYFUNCTION("""COMPUTED_VALUE"""),0.05338078291814947) -> 0.053380783 | M23: =IFERROR(__xludf.DUMMYFUNCTION("""COMPUTED_VALUE"""),0.3855421686746988) -> 0.38554217 | N23: =IFERROR(__xludf.DUMMYFUNCTION("""COMPUTED_VALUE"""),0.10843373493975904) -> 0.10843373 | O23: =IFERROR(__xludf.DUMMYFUNCTION("""COMPUTED_VALUE"""),0.11646586345381527) -> 0.11646586 | P23: =IFERROR(__xludf.DUMMYFUNCTION("""COMPUTED_VALUE"""),0.1927710843373494) -> 0.19277108 | Q23: =IFERROR(__xludf.DUMMYFUNCTION("""COMPUTED_VALUE"""),0.13654618473895583) -> 0.13654618 | R23: =IFERROR(__xludf.DUMMYFUNCTION("""COMPUTED_VALUE"""),0.060240963855421686) -> 0.060240964 | S23: =IFERROR(__xludf.DUMMYFUNCTION("""COMPUTED_VALUE"""),281.0) -> 281 | T23: =IFERROR(__xludf.DUMMYFUNCTION("""COMPUTED_VALUE"""),249.0) -> 249 | U23: {=IF($D23="","",IFERROR(_xlfn.XLOOKUP($D23,'TIR店舗一覧'!$D:$D,'TIR店舗一覧'!$E:$E,""),""))} -> YD | V23: 114 | W23: 31 | X23: 37 | Y23: 48 | Z23: 36 | AA23: 15 | AB23: 96 | AC23: 27 | AD23: 29 | AE23: 48 | AF23: 34 | AG23: 15
B24: =IFERROR(__xludf.DUMMYFUNCTION("""COMPUTED_VALUE"""),46296.0) -> 46296 | C24: =IFERROR(__xludf.DUMMYFUNCTION("""COMPUTED_VALUE"""),"信越") -> 信越 | D24: =IFERROR(__xludf.DUMMYFUNCTION("""COMPUTED_VALUE"""),3721.0) -> 3721 | E24: =IFERROR(__xludf.DUMMYFUNCTION("""COMPUTED_VALUE"""),"ジョーシン 長岡愛宕店") -> ジョーシン 長岡愛宕店 | F24: =IFERROR(__xludf.DUMMYFUNCTION("""COMPUTED_VALUE"""),19.0) -> 19 | G24: =IFERROR(__xludf.DUMMYFUNCTION("""COMPUTED_VALUE"""),0.4576271186440678) -> 0.45762712 | H24: =IFERROR(__xludf.DUMMYFUNCTION("""COMPUTED_VALUE"""),0.14124293785310735) -> 0.14124294 | I24: =IFERROR(__xludf.DUMMYFUNCTION("""COMPUTED_VALUE"""),0.04519774011299435) -> 0.04519774 | J24: =IFERROR(__xludf.DUMMYFUNCTION("""COMPUTED_VALUE"""),0.1638418079096045) -> 0.16384181 | K24: =IFERROR(__xludf.DUMMYFUNCTION("""COMPUTED_VALUE"""),0.0847457627118644) -> 0.084745763 | L24: =IFERROR(__xludf.DUMMYFUNCTION("""COMPUTED_VALUE"""),0.10734463276836158) -> 0.10734463 | M24: =IFERROR(__xludf.DUMMYFUNCTION("""COMPUTED_VALUE"""),0.28703703703703703) -> 0.28703704 | N24: =IFERROR(__xludf.DUMMYFUNCTION("""COMPUTED_VALUE"""),0.12037037037037036) -> 0.12037037 | O24: =IFERROR(__xludf.DUMMYFUNCTION("""COMPUTED_VALUE"""),0.05555555555555555) -> 0.055555556 | P24: =IFERROR(__xludf.DUMMYFUNCTION("""COMPUTED_VALUE"""),0.23148148148148148) -> 0.23148148 | Q24: =IFERROR(__xludf.DUMMYFUNCTION("""COMPUTED_VALUE"""),0.12962962962962962) -> 0.12962963 | R24: =IFERROR(__xludf.DUMMYFUNCTION("""COMPUTED_VALUE"""),0.17592592592592593) -> 0.17592593 | S24: =IFERROR(__xludf.DUMMYFUNCTION("""COMPUTED_VALUE"""),177.0) -> 177 | T24: =IFERROR(__xludf.DUMMYFUNCTION("""COMPUTED_VALUE"""),108.0) -> 108 | U24: {=IF($D24="","",IFERROR(_xlfn.XLOOKUP($D24,'TIR店舗一覧'!$D:$D,'TIR店舗一覧'!$E:$E,""),""))} -> JO | V24: 81 | W24: 25 | X24: 8 | Y24: 29 | Z24: 15 | AA24: 19 | AB24: 31 | AC24: 13 | AD24: 6 | AE24: 25 | AF24: 14 | AG24: 19
B25: =IFERROR(__xludf.DUMMYFUNCTION("""COMPUTED_VALUE"""),46296.0) -> 46296 | C25: =IFERROR(__xludf.DUMMYFUNCTION("""COMPUTED_VALUE"""),"信越") -> 信越 | D25: =IFERROR(__xludf.DUMMYFUNCTION("""COMPUTED_VALUE"""),2471.0) -> 2471 | E25: =IFERROR(__xludf.DUMMYFUNCTION("""COMPUTED_VALUE"""),"ジョーシン 上越店") -> ジョーシン 上越店 | F25: =IFERROR(__xludf.DUMMYFUNCTION("""COMPUTED_VALUE"""),23.0) -> 23 | G25: =IFERROR(__xludf.DUMMYFUNCTION("""COMPUTED_VALUE"""),0.47023809523809523) -> 0.4702381 | H25: =IFERROR(__xludf.DUMMYFUNCTION("""COMPUTED_VALUE"""),0.08928571428571429) -> 0.089285714 | I25: =IFERROR(__xludf.DUMMYFUNCTION("""COMPUTED_VALUE"""),0.041666666666666664) -> 0.041666667 | J25: =IFERROR(__xludf.DUMMYFUNCTION("""COMPUTED_VALUE"""),0.13690476190476192) -> 0.13690476 | K25: =IFERROR(__xludf.DUMMYFUNCTION("""COMPUTED_VALUE"""),0.125) -> 0.125 | L25: =IFERROR(__xludf.DUMMYFUNCTION("""COMPUTED_VALUE"""),0.13690476190476192) -> 0.13690476 | M25: =IFERROR(__xludf.DUMMYFUNCTION("""COMPUTED_VALUE"""),0.2916666666666667) -> 0.29166667 | N25: =IFERROR(__xludf.DUMMYFUNCTION("""COMPUTED_VALUE"""),0.09166666666666666) -> 0.091666667 | O25: =IFERROR(__xludf.DUMMYFUNCTION("""COMPUTED_VALUE"""),0.058333333333333334) -> 0.058333333 | P25: =IFERROR(__xludf.DUMMYFUNCTION("""COMPUTED_VALUE"""),0.19166666666666668) -> 0.19166667 | Q25: =IFERROR(__xludf.DUMMYFUNCTION("""COMPUTED_VALUE"""),0.175) -> 0.175 | R25: =IFERROR(__xludf.DUMMYFUNCTION("""COMPUTED_VALUE"""),0.19166666666666668) -> 0.19166667 | S25: =IFERROR(__xludf.DUMMYFUNCTION("""COMPUTED_VALUE"""),168.0) -> 168 | T25: =IFERROR(__xludf.DUMMYFUNCTION("""COMPUTED_VALUE"""),120.0) -> 120 | U25: {=IF($D25="","",IFERROR(_xlfn.XLOOKUP($D25,'TIR店舗一覧'!$D:$D,'TIR店舗一覧'!$E:$E,""),""))} -> JO | V25: 79 | W25: 15 | X25: 7 | Y25: 23 | Z25: 21 | AA25: 23 | AB25: 35 | AC25: 11 | AD25: 7 | AE25: 23 | AF25: 21 | AG25: 23
B26: =IFERROR(__xludf.DUMMYFUNCTION("""COMPUTED_VALUE"""),46296.0) -> 46296 | C26: =IFERROR(__xludf.DUMMYFUNCTION("""COMPUTED_VALUE"""),"信越") -> 信越 | D26: =IFERROR(__xludf.DUMMYFUNCTION("""COMPUTED_VALUE"""),1611.0) -> 1611 | E26: =IFERROR(__xludf.DUMMYFUNCTION("""COMPUTED_VALUE"""),"ジョーシン 亀貝店") -> ジョーシン 亀貝店 | F26: =IFERROR(__xludf.DUMMYFUNCTION("""COMPUTED_VALUE"""),36.0) -> 36 | G26: =IFERROR(__xludf.DUMMYFUNCTION("""COMPUTED_VALUE"""),0.3891625615763547) -> 0.38916256 | H26: =IFERROR(__xludf.DUMMYFUNCTION("""COMPUTED_VALUE"""),0.0960591133004926) -> 0.096059113 | I26: =IFERROR(__xludf.DUMMYFUNCTION("""COMPUTED_VALUE"""),0.059113300492610835) -> 0.0591133 | J26: =IFERROR(__xludf.DUMMYFUNCTION("""COMPUTED_VALUE"""),0.1625615763546798) -> 0.16256158 | K26: =IFERROR(__xludf.DUMMYFUNCTION("""COMPUTED_VALUE"""),0.2044334975369458) -> 0.2044335 | L26: =IFERROR(__xludf.DUMMYFUNCTION("""COMPUTED_VALUE"""),0.08866995073891626) -> 0.088669951 | M26: =IFERROR(__xludf.DUMMYFUNCTION("""COMPUTED_VALUE"""),0.3241590214067278) -> 0.32415902 | N26: =IFERROR(__xludf.DUMMYFUNCTION("""COMPUTED_VALUE"""),0.07339449541284404) -> 0.073394495 | O26: =IFERROR(__xludf.DUMMYFUNCTION("""COMPUTED_VALUE"""),0.06422018348623854) -> 0.064220183 | P26: =IFERROR(__xludf.DUMMYFUNCTION("""COMPUTED_VALUE"""),0.19877675840978593) -> 0.19877676 | Q26: =IFERROR(__xludf.DUMMYFUNCTION("""COMPUTED_VALUE"""),0.22935779816513763) -> 0.2293578 | R26: =IFERROR(__xludf.DUMMYFUNCTION("""COMPUTED_VALUE"""),0.11009174311926606) -> 0.11009174 | S26: =IFERROR(__xludf.DUMMYFUNCTION("""COMPUTED_VALUE"""),406.0) -> 406 | T26: =IFERROR(__xludf.DUMMYFUNCTION("""COMPUTED_VALUE"""),327.0) -> 327 | U26: {=IF($D26="","",IFERROR(_xlfn.XLOOKUP($D26,'TIR店舗一覧'!$D:$D,'TIR店舗一覧'!$E:$E,""),""))} -> JO | V26: 158 | W26: 39 | X26: 24 | Y26: 66 | Z26: 83 | AA26: 36 | AB26: 106 | AC26: 24 | AD26: 21 | AE26: 65 | AF26: 75 | AG26: 36
B27: =IFERROR(__xludf.DUMMYFUNCTION("""COMPUTED_VALUE"""),46296.0) -> 46296 | C27: =IFERROR(__xludf.DUMMYFUNCTION("""COMPUTED_VALUE"""),"信越") -> 信越 | D27: =IFERROR(__xludf.DUMMYFUNCTION("""COMPUTED_VALUE"""),3221.0) -> 3221 | E27: =IFERROR(__xludf.DUMMYFUNCTION("""COMPUTED_VALUE"""),"ジョーシン 燕三条店") -> ジョーシン 燕三条店 | F27: =IFERROR(__xludf.DUMMYFUNCTION("""COMPUTED_VALUE"""),20.0) -> 20 | G27: =IFERROR(__xludf.DUMMYFUNCTION("""COMPUTED_VALUE"""),0.4578313253012048) -> 0.45783133 | H27: =IFERROR(__xludf.DUMMYFUNCTION("""COMPUTED_VALUE"""),0.03614457831325301) -> 0.036144578 | I27: =IFERROR(__xludf.DUMMYFUNCTION("""COMPUTED_VALUE"""),0.0) -> 0 | J27: =IFERROR(__xludf.DUMMYFUNCTION("""COMPUTED_VALUE"""),0.08433734939759036) -> 0.084337349 | K27: =IFERROR(__xludf.DUMMYFUNCTION("""COMPUTED_VALUE"""),0.18072289156626506) -> 0.18072289 | L27: =IFERROR(__xludf.DUMMYFUNCTION("""COMPUTED_VALUE"""),0.24096385542168675) -> 0.24096386 | M27: =IFERROR(__xludf.DUMMYFUNCTION("""COMPUTED_VALUE"""),0.36363636363636365) -> 0.36363636 | N27: =IFERROR(__xludf.DUMMYFUNCTION("""COMPUTED_VALUE"""),0.045454545454545456) -> 0.045454545 | O27: =IFERROR(__xludf.DUMMYFUNCTION("""COMPUTED_VALUE"""),0.0) -> 0 | P27: =IFERROR(__xludf.DUMMYFUNCTION("""COMPUTED_VALUE"""),0.10606060606060606) -> 0.10606061 | Q27: =IFERROR(__xludf.DUMMYFUNCTION("""COMPUTED_VALUE"""),0.18181818181818182) -> 0.18181818 | R27: =IFERROR(__xludf.DUMMYFUNCTION("""COMPUTED_VALUE"""),0.30303030303030304) -> 0.3030303 | S27: =IFERROR(__xludf.DUMMYFUNCTION("""COMPUTED_VALUE"""),83.0) -> 83 | T27: =IFERROR(__xludf.DUMMYFUNCTION("""COMPUTED_VALUE"""),66.0) -> 66 | U27: {=IF($D27="","",IFERROR(_xlfn.XLOOKUP($D27,'TIR店舗一覧'!$D:$D,'TIR店舗一覧'!$E:$E,""),""))} -> JO | V27: 38 | W27: 3 | X27: 0 | Y27: 7 | Z27: 15 | AA27: 20 | AB27: 24 | AC27: 3 | AD27: 0 | AE27: 7 | AF27: 12 | AG27: 20
B28: =IFERROR(__xludf.DUMMYFUNCTION("""COMPUTED_VALUE"""),46296.0) -> 46296 | C28: =IFERROR(__xludf.DUMMYFUNCTION("""COMPUTED_VALUE"""),"信越") -> 信越 | D28: =IFERROR(__xludf.DUMMYFUNCTION("""COMPUTED_VALUE"""),1238.0) -> 1238 | E28: =IFERROR(__xludf.DUMMYFUNCTION("""COMPUTED_VALUE"""),"ケーズデンキ 上越インター店") -> ケーズデンキ 上越インター店 | F28: =IFERROR(__xludf.DUMMYFUNCTION("""COMPUTED_VALUE"""),20.0) -> 20 | G28: =IFERROR(__xludf.DUMMYFUNCTION("""COMPUTED_VALUE"""),0.0) -> 0 | H28: =IFERROR(__xludf.DUMMYFUNCTION("""COMPUTED_VALUE"""),0.0) -> 0 | I28: =IFERROR(__xludf.DUMMYFUNCTION("""COMPUTED_VALUE"""),0.0) -> 0 | J28: =IFERROR(__xludf.DUMMYFUNCTION("""COMPUTED_VALUE"""),0.0) -> 0 | K28: =IFERROR(__xludf.DUMMYFUNCTION("""COMPUTED_VALUE"""),0.0) -> 0 | L28: =IFERROR(__xludf.DUMMYFUNCTION("""COMPUTED_VALUE"""),1.0) -> 1 | M28: =IFERROR(__xludf.DUMMYFUNCTION("""COMPUTED_VALUE"""),0.0) -> 0 | N28: =IFERROR(__xludf.DUMMYFUNCTION("""COMPUTED_VALUE"""),0.0) -> 0 | O28: =IFERROR(__xludf.DUMMYFUNCTION("""COMPUTED_VALUE"""),0.0) -> 0 | P28: =IFERROR(__xludf.DUMMYFUNCTION("""COMPUTED_VALUE"""),0.0) -> 0 | Q28: =IFERROR(__xludf.DUMMYFUNCTION("""COMPUTED_VALUE"""),0.0) -> 0 | R28: =IFERROR(__xludf.DUMMYFUNCTION("""COMPUTED_VALUE"""),1.0) -> 1 | S28: =IFERROR(__xludf.DUMMYFUNCTION("""COMPUTED_VALUE"""),20.0) -> 20 | T28: =IFERROR(__xludf.DUMMYFUNCTION("""COMPUTED_VALUE"""),20.0) -> 20 | U28: {=IF($D28="","",IFERROR(_xlfn.XLOOKUP($D28,'TIR店舗一覧'!$D:$D,'TIR店舗一覧'!$E:$E,""),""))} -> KS | V28: 0 | W28: 0 | X28: 0 | Y28: 0 | Z28: 0 | AA28: 20 | AB28: 0 | AC28: 0 | AD28: 0 | AE28: 0 | AF28: 0 | AG28: 20
B29: =IFERROR(__xludf.DUMMYFUNCTION("""COMPUTED_VALUE"""),46296.0) -> 46296 | C29: =IFERROR(__xludf.DUMMYFUNCTION("""COMPUTED_VALUE"""),"信越") -> 信越 | D29: =IFERROR(__xludf.DUMMYFUNCTION("""COMPUTED_VALUE"""),1505.0) -> 1505 | E29: =IFERROR(__xludf.DUMMYFUNCTION("""COMPUTED_VALUE"""),"ケーズデンキ 女池インター本店") -> ケーズデンキ 女池インター本店 | F29: =IFERROR(__xludf.DUMMYFUNCTION("""COMPUTED_VALUE"""),32.0) -> 32 | G29: =IFERROR(__xludf.DUMMYFUNCTION("""COMPUTED_VALUE"""),0.0) -> 0 | H29: =IFERROR(__xludf.DUMMYFUNCTION("""COMPUTED_VALUE"""),0.0) -> 0 | I29: =IFERROR(__xludf.DUMMYFUNCTION("""COMPUTED_VALUE"""),0.0) -> 0 | J29: =IFERROR(__xludf.DUMMYFUNCTION("""COMPUTED_VALUE"""),0.0) -> 0 | K29: =IFERROR(__xludf.DUMMYFUNCTION("""COMPUTED_VALUE"""),0.0) -> 0 | L29: =IFERROR(__xludf.DUMMYFUNCTION("""COMPUTED_VALUE"""),1.0) -> 1 | M29: =IFERROR(__xludf.DUMMYFUNCTION("""COMPUTED_VALUE"""),0.0) -> 0 | N29: =IFERROR(__xludf.DUMMYFUNCTION("""COMPUTED_VALUE"""),0.0) -> 0 | O29: =IFERROR(__xludf.DUMMYFUNCTION("""COMPUTED_VALUE"""),0.0) -> 0 | P29: =IFERROR(__xludf.DUMMYFUNCTION("""COMPUTED_VALUE"""),0.0) -> 0 | Q29: =IFERROR(__xludf.DUMMYFUNCTION("""COMPUTED_VALUE"""),0.0) -> 0 | R29: =IFERROR(__xludf.DUMMYFUNCTION("""COMPUTED_VALUE"""),1.0) -> 1 | S29: =IFERROR(__xludf.DUMMYFUNCTION("""COMPUTED_VALUE"""),32.0) -> 32 | T29: =IFERROR(__xludf.DUMMYFUNCTION("""COMPUTED_VALUE"""),32.0) -> 32 | U29: {=IF($D29="","",IFERROR(_xlfn.XLOOKUP($D29,'TIR店舗一覧'!$D:$D,'TIR店舗一覧'!$E:$E,""),""))} -> KS | V29: 0 | W29: 0 | X29: 0 | Y29: 0 | Z29: 0 | AA29: 32 | AB29: 0 | AC29: 0 | AD29: 0 | AE29: 0 | AF29: 0 | AG29: 32
B30: =IFERROR(__xludf.DUMMYFUNCTION("""COMPUTED_VALUE"""),46296.0) -> 46296 | C30: =IFERROR(__xludf.DUMMYFUNCTION("""COMPUTED_VALUE"""),"信越") -> 信越 | D30: =IFERROR(__xludf.DUMMYFUNCTION("""COMPUTED_VALUE"""),1036.0) -> 1036 | E30: =IFERROR(__xludf.DUMMYFUNCTION("""COMPUTED_VALUE"""),"エディオン 塩尻店") -> エディオン 塩尻店 | F30: =IFERROR(__xludf.DUMMYFUNCTION("""COMPUTED_VALUE"""),24.0) -> 24 | G30: =IFERROR(__xludf.DUMMYFUNCTION("""COMPUTED_VALUE"""),0.0) -> 0 | H30: =IFERROR(__xludf.DUMMYFUNCTION("""COMPUTED_VALUE"""),0.0) -> 0 | I30: =IFERROR(__xludf.DUMMYFUNCTION("""COMPUTED_VALUE"""),0.0) -> 0 | J30: =IFERROR(__xludf.DUMMYFUNCTION("""COMPUTED_VALUE"""),0.0) -> 0 | K30: =IFERROR(__xludf.DUMMYFUNCTION("""COMPUTED_VALUE"""),0.0) -> 0 | L30: =IFERROR(__xludf.DUMMYFUNCTION("""COMPUTED_VALUE"""),1.0) -> 1 | M30: =IFERROR(__xludf.DUMMYFUNCTION("""COMPUTED_VALUE"""),0.0) -> 0 | N30: =IFERROR(__xludf.DUMMYFUNCTION("""COMPUTED_VALUE"""),0.0) -> 0 | O30: =IFERROR(__xludf.DUMMYFUNCTION("""COMPUTED_VALUE"""),0.0) -> 0 | P30: =IFERROR(__xludf.DUMMYFUNCTION("""COMPUTED_VALUE"""),0.0) -> 0 | Q30: =IFERROR(__xludf.DUMMYFUNCTION("""COMPUTED_VALUE"""),0.0) -> 0 | R30: =IFERROR(__xludf.DUMMYFUNCTION("""COMPUTED_VALUE"""),1.0) -> 1 | S30: =IFERROR(__xludf.DUMMYFUNCTION("""COMPUTED_VALUE"""),24.0) -> 24 | T30: =IFERROR(__xludf.DUMMYFUNCTION("""COMPUTED_VALUE"""),24.0) -> 24 | U30: {=IF($D30="","",IFERROR(_xlfn.XLOOKUP($D30,'TIR店舗一覧'!$D:$D,'TIR店舗一覧'!$E:$E,""),""))} -> ED | V30: 0 | W30: 0 | X30: 0 | Y30: 0 | Z30: 0 | AA30: 24 | AB30: 0 | AC30: 0 | AD30: 0 | AE30: 0 | AF30: 0 | AG30: 24
B31: =IFERROR(__xludf.DUMMYFUNCTION("""COMPUTED_VALUE"""),46296.0) -> 46296 | C31: =IFERROR(__xludf.DUMMYFUNCTION("""COMPUTED_VALUE"""),"信越") -> 信越 | D31: =IFERROR(__xludf.DUMMYFUNCTION("""COMPUTED_VALUE"""),7850.0) -> 7850 | E31: =IFERROR(__xludf.DUMMYFUNCTION("""COMPUTED_VALUE"""),"YAMADA web.com 長岡店") -> YAMADA web.com 長岡店 | F31: =IFERROR(__xludf.DUMMYFUNCTION("""COMPUTED_VALUE"""),31.0) -> 31 | G31: =IFERROR(__xludf.DUMMYFUNCTION("""COMPUTED_VALUE"""),0.2623762376237624) -> 0.26237624 | H31: =IFERROR(__xludf.DUMMYFUNCTION("""COMPUTED_VALUE"""),0.0594059405940594) -> 0.059405941 | I31: =IFERROR(__xludf.DUMMYFUNCTION("""COMPUTED_VALUE"""),0.12871287128712872) -> 0.12871287 | J31: =IFERROR(__xludf.DUMMYFUNCTION("""COMPUTED_VALUE"""),0.1188118811881188) -> 0.11881188 | K31: =IFERROR(__xludf.DUMMYFUNCTION("""COMPUTED_VALUE"""),0.27722772277227725) -> 0.27722772 | L31: =IFERROR(__xludf.DUMMYFUNCTION("""COMPUTED_VALUE"""),0.15346534653465346) -> 0.15346535 | M31: =IFERROR(__xludf.DUMMYFUNCTION("""COMPUTED_VALUE"""),0.2303370786516854) -> 0.23033708 | N31: =IFERROR(__xludf.DUMMYFUNCTION("""COMPUTED_VALUE"""),0.06179775280898876) -> 0.061797753 | O31: =IFERROR(__xludf.DUMMYFUNCTION("""COMPUTED_VALUE"""),0.10674157303370786) -> 0.10674157 | P31: =IFERROR(__xludf.DUMMYFUNCTION("""COMPUTED_VALUE"""),0.12359550561797752) -> 0.12359551 | Q31: =IFERROR(__xludf.DUMMYFUNCTION("""COMPUTED_VALUE"""),0.30337078651685395) -> 0.30337079 | R31: =IFERROR(__xludf.DUMMYFUNCTION("""COMPUTED_VALUE"""),0.17415730337078653) -> 0.1741573 | S31: =IFERROR(__xludf.DUMMYFUNCTION("""COMPUTED_VALUE"""),202.0) -> 202 | T31: =IFERROR(__xludf.DUMMYFUNCTION("""COMPUTED_VALUE"""),178.0) -> 178 | U31: {=IF($D31="","",IFERROR(_xlfn.XLOOKUP($D31,'TIR店舗一覧'!$D:$D,'TIR店舗一覧'!$E:$E,""),""))} -> YD | V31: 53 | W31: 12 | X31: 26 | Y31: 24 | Z31: 56 | AA31: 31 | AB31: 41 | AC31: 11 | AD31: 19 | AE31: 22 | AF31: 54 | AG31: 31
B32: =IFERROR(__xludf.DUMMYFUNCTION("""COMPUTED_VALUE"""),46296.0) -> 46296 | C32: =IFERROR(__xludf.DUMMYFUNCTION("""COMPUTED_VALUE"""),"信越") -> 信越 | D32: =IFERROR(__xludf.DUMMYFUNCTION("""COMPUTED_VALUE"""),7822.0) -> 7822 | E32: =IFERROR(__xludf.DUMMYFUNCTION("""COMPUTED_VALUE"""),"Tecc LIFE SELECT 長野SBC通り店") -> Tecc LIFE SELECT 長野SBC通り店 | F32: =IFERROR(__xludf.DUMMYFUNCTION("""COMPUTED_VALUE"""),27.0) -> 27 | G32: =IFERROR(__xludf.DUMMYFUNCTION("""COMPUTED_VALUE"""),0.21727019498607242) -> 0.21727019 | H32: =IFERROR(__xludf.DUMMYFUNCTION("""COMPUTED_VALUE"""),0.10584958217270195) -> 0.10584958 | I32: =IFERROR(__xludf.DUMMYFUNCTION("""COMPUTED_VALUE"""),0.2618384401114206) -> 0.26183844 | J32: =IFERROR(__xludf.DUMMYFUNCTION("""COMPUTED_VALUE"""),0.11977715877437325) -> 0.11977716 | K32: =IFERROR(__xludf.DUMMYFUNCTION("""COMPUTED_VALUE"""),0.2200557103064067) -> 0.22005571 | L32: =IFERROR(__xludf.DUMMYFUNCTION("""COMPUTED_VALUE"""),0.07520891364902507) -> 0.075208914 | M32: =IFERROR(__xludf.DUMMYFUNCTION("""COMPUTED_VALUE"""),0.17846153846153845) -> 0.17846154 | N32: =IFERROR(__xludf.DUMMYFUNCTION("""COMPUTED_VALUE"""),0.11384615384615385) -> 0.11384615 | O32: =IFERROR(__xludf.DUMMYFUNCTION("""COMPUTED_VALUE"""),0.24923076923076923) -> 0.24923077 | P32: =IFERROR(__xludf.DUMMYFUNCTION("""COMPUTED_VALUE"""),0.13230769230769232) -> 0.13230769 | Q32: =IFERROR(__xludf.DUMMYFUNCTION("""COMPUTED_VALUE"""),0.24307692307692308) -> 0.24307692 | R32: =IFERROR(__xludf.DUMMYFUNCTION("""COMPUTED_VALUE"""),0.08307692307692308) -> 0.083076923 | S32: =IFERROR(__xludf.DUMMYFUNCTION("""COMPUTED_VALUE"""),359.0) -> 359 | T32: =IFERROR(__xludf.DUMMYFUNCTION("""COMPUTED_VALUE"""),325.0) -> 325 | U32: {=IF($D32="","",IFERROR(_xlfn.XLOOKUP($D32,'TIR店舗一覧'!$D:$D,'TIR店舗一覧'!$E:$E,""),""))} -> YD | V32: 78 | W32: 38 | X32: 94 | Y32: 43 | Z32: 79 | AA32: 27 | AB32: 58 | AC32: 37 | AD32: 81 | AE32: 43 | AF32: 79 | AG32: 27
B33: =IFERROR(__xludf.DUMMYFUNCTION("""COMPUTED_VALUE"""),46296.0) -> 46296 | C33: =IFERROR(__xludf.DUMMYFUNCTION("""COMPUTED_VALUE"""),"信越") -> 信越 | D33: =IFERROR(__xludf.DUMMYFUNCTION("""COMPUTED_VALUE"""),8633.0) -> 8633 | E33: =IFERROR(__xludf.DUMMYFUNCTION("""COMPUTED_VALUE"""),"Tecc LIFE SELECT 須坂店") -> Tecc LIFE SELECT 須坂店 | F33: =IFERROR(__xludf.DUMMYFUNCTION("""COMPUTED_VALUE"""),"-") -> - | G33: =IFERROR(__xludf.DUMMYFUNCTION("""COMPUTED_VALUE"""),"-") -> - | H33: =IFERROR(__xludf.DUMMYFUNCTION("""COMPUTED_VALUE"""),"-") -> - | I33: =IFERROR(__xludf.DUMMYFUNCTION("""COMPUTED_VALUE"""),"-") -> - | J33: =IFERROR(__xludf.DUMMYFUNCTION("""COMPUTED_VALUE"""),"-") -> - | K33: =IFERROR(__xludf.DUMMYFUNCTION("""COMPUTED_VALUE"""),"-") -> - | L33: =IFERROR(__xludf.DUMMYFUNCTION("""COMPUTED_VALUE"""),"-") -> - | M33: =IFERROR(__xludf.DUMMYFUNCTION("""COMPUTED_VALUE"""),"-") -> - | ... T33: =IFERROR(__xludf.DUMMYFUNCTION("""COMPUTED_VALUE"""),"-") -> - | U33: {=IF($D33="","",IFERROR(_xlfn.XLOOKUP($D33,'TIR店舗一覧'!$D:$D,'TIR店舗一覧'!$E:$E,""),""))} -> YD | V33: 0 | W33: 0 | X33: 0 | Y33: 0 | Z33: 0 | AA33: 0 | AB33: 0 | AC33: 0 | AD33: 0 | AE33: 0 | AF33: 0 | AG33: 0
